Workbook

Sheet 總計
I1: 財產配置 | J1: 市值 | K1: 成本 | L1: 損益 | M1: 損益率 | Q1: 股票代號 | R1: 股票名稱 | S1: 成本 | T1: 現價 | U1: 持有股數 | V1: 損益 | W1: 損益率 | X1: 總投資成本 | Y1: 市值 | AC1: 日期 | AD1: 郵局 | AE1: 中國信託 | AF1: 富邦 | AG1: 富邦外幣 | AH1: 富邦證卷 | AI1: 富邦證卷複委託 | AJ1: 國泰 | AK1: line bank | AL1: firstrade-cash(TWD) | AM1: firstrade-position(TWD) | AN1: firstrade-cash(USD) | AO1: firstrade-position(USD) | AP1: 加總 | AQ1: 現金 | AR1: 台股 | AS1: 美股 | AT1: 變化 | AU1: 變化每日
I2: 台股 | J2: =sum('台股庫存'!K1) -> 299509.45 | K2: ='台股庫存'!M1 -> 240415.82 | L2: =J2-K2 -> 59093.63 | M2: =L2/K2 -> 0.24579759 | Q2: =IFERROR(__xludf.DUMMYFUNCTION("{ FILTER({ '美股庫存'!A2:B1000, '美股庫存'!C2:D1000 * J6, '美股庫存'!E2:G1000, '美股庫存'!H2:I1000 * J6 }, '美股庫存'!A2:A1000<>""""); FILTER('台股庫存'!A2:I1000, '台股庫存'!A2:A1000<>"""") }"),"TSLA") -> TSLA | R2: =IFERROR(__xludf.DUMMYFUNCTION("""COMPUTED_VALUE"""),"Tesla, Inc.") -> Tesla, Inc. | S2: =IFERROR(__xludf.DUMMYFUNCTION("""COMPUTED_VALUE"""),9131.35471257973) -> 9131.3547 | T2: =IFERROR(__xludf.DUMMYFUNCTION("""COMPUTED_VALUE"""),12617.819670000003) -> 12617.82 | U2: =IFERROR(__xludf.DUMMYFUNCTION("""COMPUTED_VALUE"""),18.5) -> 18.5 | V2: =IFERROR(__xludf.DUMMYFUNCTION("""COMPUTED_VALUE"""),2065.110675000001) -> 2065.1107 | W2: =IFERROR(__xludf.DUMMYFUNCTION("""COMPUTED_VALUE"""),0.38181245468617864) -> 0.38181245 | X2: =IFERROR(__xludf.DUMMYFUNCTION("""COMPUTED_VALUE"""),168930.062182725) -> 168930.06 | Y2: =IFERROR(__xludf.DUMMYFUNCTION("""COMPUTED_VALUE"""),233429.66389500003) -> 233429.66 | AC2: 45703 | AD2: 890970 | AE2: 248170 | AF2: 339611 | AG2: 9946 | AH2: 100769 | AI2: 119874 | AJ2: 0 | AK2: 199851 | AL2: 215029.41 | AM2: 284454.04 | AN2: 6575.18 | AO2: 8698.05 | AP2: =sum(AD2:AM2) -> 2408674.5 | AQ2: =sum(AD2:AG2)+sum(AJ2:AL2) -> 1903577.4 | AR2: =AH2 -> 100769 | AS2: =AI2+AM2 -> 404328.04 | AT2: =AP2-AP1 -> #VALUE! | AU2: =AT2/(AC2-AC1) -> #VALUE!
I3: 美股(TWD) | J3: =J4*J6 -> 1308607.1 | K3: =sum('美股庫存'!J:J) -> 1111114.9 | L3: =J3-K3 -> 197492.27 | M3: =L3/K3 -> 0.17774245 | Q3: =IFERROR(__xludf.DUMMYFUNCTION("""COMPUTED_VALUE"""),"TSLL") -> TSLL | R3: =IFERROR(__xludf.DUMMYFUNCTION("""COMPUTED_VALUE"""),"Direxion Daily TSLA Bull 2X Shares") -> Direxion Daily TSLA Bull 2X Shares | S3: =IFERROR(__xludf.DUMMYFUNCTION("""COMPUTED_VALUE"""),352.6999273163264) -> 352.69993 | T3: =IFERROR(__xludf.DUMMYFUNCTION("""COMPUTED_VALUE"""),515.6568300000001) -> 515.65683 | U3: =IFERROR(__xludf.DUMMYFUNCTION("""COMPUTED_VALUE"""),98.0) -> 98 | V3: =IFERROR(__xludf.DUMMYFUNCTION("""COMPUTED_VALUE"""),511.31100000000083) -> 511.311 | W3: =IFERROR(__xludf.DUMMYFUNCTION("""COMPUTED_VALUE"""),0.4620270378948006) -> 0.46202704 | X3: =IFERROR(__xludf.DUMMYFUNCTION("""COMPUTED_VALUE"""),34564.59287699999) -> 34564.593 | Y3: =IFERROR(__xludf.DUMMYFUNCTION("""COMPUTED_VALUE"""),50534.36934000001) -> 50534.369 | AC3: 45715 | AD3: 764438 | AE3: 257372 | AF3: 184668 | AG3: 9950 | AH3: 143052 | AI3: 145552 | AJ3: 5419 | AK3: 0 | AL3: 227881.9 | AM3: 576375.65 | AN3: 6946.9 | AO3: 17570.61 | AP3: =sum(AD3:AM3) -> 2314708.6 | AQ3: =sum(AD3:AG3)+sum(AJ3:AL3) -> 1449728.9 | AR3: =AH3 -> 143052 | AS3: =AI3+AM3 -> 721927.65 | AT3: =AP3-AP2 -> -93965.9 | AU3: =AT3/(AC3-AC2) -> -7830.4917
I4: 美股(USD) | J4: =sum('美股庫存'!I:I)+'美股已實現損益'!V6 -> 41898.221 | K4: =sum('美股庫存'!H:H) -> 33937.574 | L4: =J4-K4 -> 7960.6467 | M4: =L4/K4 -> 0.23456735 | Q4: =IFERROR(__xludf.DUMMYFUNCTION("""COMPUTED_VALUE"""),"QQQ") -> QQQ | R4: =IFERROR(__xludf.DUMMYFUNCTION("""COMPUTED_VALUE"""),"Invesco QQQ Trust") -> Invesco QQQ Trust | S4: =IFERROR(__xludf.DUMMYFUNCTION("""COMPUTED_VALUE"""),16242.29242439295) -> 16242.292 | T4: =IFERROR(__xludf.DUMMYFUNCTION("""COMPUTED_VALUE"""),18735.73971) -> 18735.74 | U4: =IFERROR(__xludf.DUMMYFUNCTION("""COMPUTED_VALUE"""),11.007950000000001) -> 11.00795 | V4: =IFERROR(__xludf.DUMMYFUNCTION("""COMPUTED_VALUE"""),878.8058479044003) -> 878.80585 | W4: =IFERROR(__xludf.DUMMYFUNCTION("""COMPUTED_VALUE"""),0.15351572428669916) -> 0.15351572 | X4: =IFERROR(__xludf.DUMMYFUNCTION("""COMPUTED_VALUE"""),178794.34289309641) -> 178794.34 | Y4: =IFERROR(__xludf.DUMMYFUNCTION("""COMPUTED_VALUE"""),206242.08594069455) -> 206242.09 | AC4: 45735 | AD4: 523937 | AE4: 194589 | AF4: 131746 | AG4: 0 | AH4: 185018 | AI4: 128955 | AJ4: 25352 | AK4: 0 | AL4: 94371.48 | AM4: 792693 | AN4: 2856.15 | AO4: 23990.83 | AP4: =sum(AD4:AM4) -> 2076661.5 | AQ4: =sum(AD4:AG4)+sum(AJ4:AL4) -> 969995.48 | AR4: =AH4 -> 185018 | AS4: =AI4+AM4 -> 921648 | AT4: =AP4-AP3 -> -238047.07 | AU4: =AT4/(AC4-AC3) -> -11902.353
I5: 加總 | J5: =SUM(J2:J3) -> 1608116.6 | K5: =SUM(K2:K3) -> 1351530.7 | L5: =J5-K5 -> 256585.9 | M5: =L5/K5 -> 0.18984837 | Q5: =IFERROR(__xludf.DUMMYFUNCTION("""COMPUTED_VALUE"""),"VOO") -> VOO | R5: =IFERROR(__xludf.DUMMYFUNCTION("""COMPUTED_VALUE"""),"Vanguard S&P 500 ETF") -> Vanguard S&P 500 ETF | S5: =IFERROR(__xludf.DUMMYFUNCTION("""COMPUTED_VALUE"""),16977.58739915609) -> 16977.587 | T5: =IFERROR(__xludf.DUMMYFUNCTION("""COMPUTED_VALUE"""),19027.143600000003) -> 19027.144 | U5: =IFERROR(__xludf.DUMMYFUNCTION("""COMPUTED_VALUE"""),7.0642700000000005) -> 7.06427 | V5: =IFERROR(__xludf.DUMMYFUNCTION("""COMPUTED_VALUE"""),463.56796922920057) -> 463.56797 | W5: =IFERROR(__xludf.DUMMYFUNCTION("""COMPUTED_VALUE"""),0.12072128699191911) -> 0.12072129 | X5: =IFERROR(__xludf.DUMMYFUNCTION("""COMPUTED_VALUE"""),119934.2613362364) -> 119934.26 | Y5: =IFERROR(__xludf.DUMMYFUNCTION("""COMPUTED_VALUE"""),134412.87971917202) -> 134412.88 | AC5: 45766 | AD5: 494438 | AE5: 179653 | AF5: 81328 | AG5: 0 | AH5: 217199 | AI5: 83115 | AJ5: 23070 | AK5: 0 | AL5: 803.99328 | AM5: 836809.02 | AN5: 24.72 | AO5: 25728.97 | AP5: =sum(AD5:AM5) -> 1916416 | AQ5: =sum(AD5:AG5)+sum(AJ5:AL5) -> 779292.99 | AR5: =AH5 -> 217199 | AS5: =AI5+AM5 -> 919924.02 | AT5: =AP5-AP4 -> -160245.47 | AU5: =AT5/(AC5-AC4) -> -5169.2087
I6: 美元匯率 | J6: =IFERROR(__xludf.DUMMYFUNCTION("GOOGLEFINANCE(""CURRENCY:USDTWD"")"),31.233000000000004) -> 31.233 | Q6: =IFERROR(__xludf.DUMMYFUNCTION("""COMPUTED_VALUE"""),"NVDA") -> NVDA | R6: =IFERROR(__xludf.DUMMYFUNCTION("""COMPUTED_VALUE"""),"NVIDIA Corporation") -> NVIDIA Corporation | S6: =IFERROR(__xludf.DUMMYFUNCTION("""COMPUTED_VALUE"""),4404.9127173176485) -> 4404.9127 | T6: =IFERROR(__xludf.DUMMYFUNCTION("""COMPUTED_VALUE"""),5825.579160000001) -> 5825.5792 | U6: =IFERROR(__xludf.DUMMYFUNCTION("""COMPUTED_VALUE"""),17.0) -> 17 | V6: =IFERROR(__xludf.DUMMYFUNCTION("""COMPUTED_VALUE"""),773.2631999999994) -> 773.2632 | W6: =IFERROR(__xludf.DUMMYFUNCTION("""COMPUTED_VALUE"""),0.3225186363164672) -> 0.32251864 | X6: =IFERROR(__xludf.DUMMYFUNCTION("""COMPUTED_VALUE"""),74883.51619440003) -> 74883.516 | Y6: =IFERROR(__xludf.DUMMYFUNCTION("""COMPUTED_VALUE"""),99034.84572000001) -> 99034.846 | AC6: 45798 | AD6: 469501 | AE6: 139590 | AF6: 69118 | AG6: 0 | AH6: 241770 | AI6: 136359 | AJ6: 5887 | AK6: 0 | AL6: 10524.925 | AM6: 929172.43 | AN6: 348.92 | AO6: 30803.72 | AP6: =sum(AD6:AM6) -> 2001922.4 | AQ6: =sum(AD6:AG6)+sum(AJ6:AL6) -> 694620.93 | AR6: =AH6 -> 241770 | AS6: =AI6+AM6 -> 1065531.4 | AT6: =AP6-AP5 -> 85506.341 | AU6: =AT6/(AC6-AC5) -> 2672.0732
Q7: =IFERROR(__xludf.DUMMYFUNCTION("""COMPUTED_VALUE"""),"RDDT") -> RDDT | R7: =IFERROR(__xludf.DUMMYFUNCTION("""COMPUTED_VALUE"""),"Reddit, Inc.") -> Reddit, Inc. | S7: =IFERROR(__xludf.DUMMYFUNCTION("""COMPUTED_VALUE"""),4862.7274945780255) -> 4862.7275 | T7: =IFERROR(__xludf.DUMMYFUNCTION("""COMPUTED_VALUE"""),5864.932740000001) -> 5864.9327 | U7: =IFERROR(__xludf.DUMMYFUNCTION("""COMPUTED_VALUE"""),13.875820000000001) -> 13.87582 | V7: =IFERROR(__xludf.DUMMYFUNCTION("""COMPUTED_VALUE"""),445.24764155) -> 445.24764 | W7: =IFERROR(__xludf.DUMMYFUNCTION("""COMPUTED_VALUE"""),0.2060994054343865) -> 0.20609941 | X7: =IFERROR(__xludf.DUMMYFUNCTION("""COMPUTED_VALUE"""),67474.33142381567) -> 67474.331 | Y7: =IFERROR(__xludf.DUMMYFUNCTION("""COMPUTED_VALUE"""),81380.75101234682) -> 81380.751 | AC7: 45830 | AD7: 462486 | AE7: 102938 | AF7: 70784 | AG7: 25 | AH7: 250247 | AI7: 129900 | AJ7: 2131 | AK7: 66 | AL7: 28750.234 | AM7: 895526.73 | AN7: 972.31 | AO7: 30286 | AP7: =sum(AD7:AM7) -> 1942854 | AQ7: =sum(AD7:AG7)+sum(AJ7:AL7) -> 667180.23 | AR7: =AH7 -> 250247 | AS7: =AI7+AM7 -> 1025426.7 | AT7: =AP7-AP6 -> -59068.386 | AU7: =AT7/(AC7-AC6) -> -1845.8871
Q8: =IFERROR(__xludf.DUMMYFUNCTION("""COMPUTED_VALUE"""),"COST") -> COST | R8: =IFERROR(__xludf.DUMMYFUNCTION("""COMPUTED_VALUE"""),"Costco Wholesale Corporation") -> Costco Wholesale Corporation | S8: =IFERROR(__xludf.DUMMYFUNCTION("""COMPUTED_VALUE"""),31827.845498749997) -> 31827.845 | T8: =IFERROR(__xludf.DUMMYFUNCTION("""COMPUTED_VALUE"""),27816.109800000006) -> 27816.11 | U8: =IFERROR(__xludf.DUMMYFUNCTION("""COMPUTED_VALUE"""),2.4000000000000004) -> 2.4 | V8: =IFERROR(__xludf.DUMMYFUNCTION("""COMPUTED_VALUE"""),-308.2689999999993) -> -308.269 | W8: =IFERROR(__xludf.DUMMYFUNCTION("""COMPUTED_VALUE"""),-0.12604484016700243) -> -0.12604484 | X8: =IFERROR(__xludf.DUMMYFUNCTION("""COMPUTED_VALUE"""),76386.829197) -> 76386.829 | Y8: =IFERROR(__xludf.DUMMYFUNCTION("""COMPUTED_VALUE"""),66758.66352000003) -> 66758.664 | AC8: 45861 | AD8: 452680 | AE8: 105283 | AF8: 70786 | AG8: 25 | AH8: 267538 | AI8: 135944 | AJ8: 1201 | AK8: 66 | AL8: 5409.0491 | AM8: 961147.49 | AN8: 183.97 | AO8: 32690.09 | AP8: =sum(AD8:AM8) -> 2000079.5 | AQ8: =sum(AD8:AG8)+sum(AJ8:AL8) -> 635450.05 | AR8: =AH8 -> 267538 | AS8: =AI8+AM8 -> 1097091.5 | AT8: =AP8-AP7 -> 57225.569 | AU8: =AT8/(AC8-AC7) -> 1845.9861
Q9: =IFERROR(__xludf.DUMMYFUNCTION("""COMPUTED_VALUE"""),"PLTR") -> PLTR | R9: =IFERROR(__xludf.DUMMYFUNCTION("""COMPUTED_VALUE"""),"Palantir Technologies Inc.") -> Palantir Technologies Inc. | S9: =IFERROR(__xludf.DUMMYFUNCTION("""COMPUTED_VALUE"""),3490.600080000001) -> 3490.6001 | T9: =IFERROR(__xludf.DUMMYFUNCTION("""COMPUTED_VALUE"""),5166.56286) -> 5166.5629 | U9: =IFERROR(__xludf.DUMMYFUNCTION("""COMPUTED_VALUE"""),10.0) -> 10 | V9: =IFERROR(__xludf.DUMMYFUNCTION("""COMPUTED_VALUE"""),536.5999999999997) -> 536.6 | W9: =IFERROR(__xludf.DUMMYFUNCTION("""COMPUTED_VALUE"""),0.48013600572655657) -> 0.48013601 | X9: =IFERROR(__xludf.DUMMYFUNCTION("""COMPUTED_VALUE"""),34906.00080000001) -> 34906.001 | Y9: =IFERROR(__xludf.DUMMYFUNCTION("""COMPUTED_VALUE"""),51665.628600000004) -> 51665.629 | AC9: 45912 | AD9: 401784 | AE9: 61656 | AF9: 44910 | AG9: 26 | AH9: 271143 | AI9: 184147 | AJ9: 1676 | AK9: 66 | AL9: 4066.3365 | AM9: 1114007.9 | AN9: 134.32 | AO9: 36798.12 | AP9: =sum(AD9:AM9) -> 2083482.2 | AQ9: =sum(AD9:AG9)+sum(AJ9:AL9) -> 514184.34 | AR9: =AH9 -> 271143 | AS9: =AI9+AM9 -> 1298154.9 | AT9: =AP9-AP8 -> 83402.681 | AU9: =AT9/(AC9-AC8) -> 1635.3467
Q10: =IFERROR(__xludf.DUMMYFUNCTION("""COMPUTED_VALUE"""),"QLD") -> QLD | R10: =IFERROR(__xludf.DUMMYFUNCTION("""COMPUTED_VALUE"""),"ProShares Ultra QQQ") -> ProShares Ultra QQQ | S10: =IFERROR(__xludf.DUMMYFUNCTION("""COMPUTED_VALUE"""),3128.3890148409596) -> 3128.389 | T10: =IFERROR(__xludf.DUMMYFUNCTION("""COMPUTED_VALUE"""),4222.389270000001) -> 4222.3893 | U10: =IFERROR(__xludf.DUMMYFUNCTION("""COMPUTED_VALUE"""),10.0) -> 10 | V10: =IFERROR(__xludf.DUMMYFUNCTION("""COMPUTED_VALUE"""),350.27062887299996) -> 350.27063 | W10: =IFERROR(__xludf.DUMMYFUNCTION("""COMPUTED_VALUE"""),0.349700836427038) -> 0.34970084 | X10: =IFERROR(__xludf.DUMMYFUNCTION("""COMPUTED_VALUE"""),31283.8901484096) -> 31283.89 | Y10: =IFERROR(__xludf.DUMMYFUNCTION("""COMPUTED_VALUE"""),42223.89270000001) -> 42223.893 | AC10: 45960 | AD10: 383520 | AE10: 49933 | AF10: 27098 | AG10: 26 | AH10: 307726 | AI10: 184932 | AJ10: 13905 | AK10: 66 | AL10: 3566.908 | AM10: 1259924.2 | AN10: 116.22 | AO10: 41051.91 | AP10: =sum(AD10:AM10) -> 2230697.1 | AQ10: =sum(AD10:AG10)+sum(AJ10:AL10) -> 478114.91 | AR10: =AH10 -> 307726 | AS10: =AI10+AM10 -> 1444856.2 | AT10: =AP10-AP9 -> 147214.86 | AU10: =AT10/(AC10-AC9) -> 3066.9762
Q11: =IFERROR(__xludf.DUMMYFUNCTION("""COMPUTED_VALUE"""),"GOOGL") -> GOOGL | R11: =IFERROR(__xludf.DUMMYFUNCTION("""COMPUTED_VALUE"""),"Alphabet Inc.") -> Alphabet Inc. | S11: =IFERROR(__xludf.DUMMYFUNCTION("""COMPUTED_VALUE"""),5798.897155133334) -> 5798.8972 | T11: =IFERROR(__xludf.DUMMYFUNCTION("""COMPUTED_VALUE"""),9145.33473) -> 9145.3347 | U11: =IFERROR(__xludf.DUMMYFUNCTION("""COMPUTED_VALUE"""),4.5) -> 4.5 | V11: =IFERROR(__xludf.DUMMYFUNCTION("""COMPUTED_VALUE"""),482.14930000000004) -> 482.1493 | W11: =IFERROR(__xludf.DUMMYFUNCTION("""COMPUTED_VALUE"""),0.5770817252560367) -> 0.57708173 | X11: =IFERROR(__xludf.DUMMYFUNCTION("""COMPUTED_VALUE"""),26095.037198100003) -> 26095.037 | Y11: =IFERROR(__xludf.DUMMYFUNCTION("""COMPUTED_VALUE"""),41154.006285) -> 41154.006 | AP11: =sum(AD11:AM11) -> 0 | AQ11: =sum(AD11:AG11)+sum(AJ11:AL11) -> 0 | AR11: =AH11 | AS11: =AI11+AM11 -> 0 | AT11: =AP11-AP10 -> -2230697.1 | AU11: =AT11/(AC11-AC10) -> 48.53562
Q12: =IFERROR(__xludf.DUMMYFUNCTION("""COMPUTED_VALUE"""),"AGGU.SW") -> AGGU.SW | R12: =IFERROR(__xludf.DUMMYFUNCTION("""COMPUTED_VALUE"""),"iShares Core Global Aggregate Bond UCITS ETF USD Hedged (Acc)") -> iShares Core Global Aggregate Bond UCITS ETF USD Hedged (Acc) | S12: =IFERROR(__xludf.DUMMYFUNCTION("""COMPUTED_VALUE"""),175.01161686000003) -> 175.01162 | T12: =IFERROR(__xludf.DUMMYFUNCTION("""COMPUTED_VALUE"""),180.72038460000002) -> 180.72038 | U12: =IFERROR(__xludf.DUMMYFUNCTION("""COMPUTED_VALUE"""),200.0) -> 200 | V12: =IFERROR(__xludf.DUMMYFUNCTION("""COMPUTED_VALUE"""),36.55600000000004) -> 36.556 | W12: =IFERROR(__xludf.DUMMYFUNCTION("""COMPUTED_VALUE"""),0.03261936460233218) -> 0.032619365 | X12: =IFERROR(__xludf.DUMMYFUNCTION("""COMPUTED_VALUE"""),35002.323372000006) -> 35002.323 | Y12: =IFERROR(__xludf.DUMMYFUNCTION("""COMPUTED_VALUE"""),36144.07692000001) -> 36144.077 | AP12: =sum(AD12:AM12) -> 0 | AQ12: =sum(AD12:AG12)+sum(AJ12:AL12) -> 0 | AR12: =AH12 | AS12: =AI12+AM12 -> 0 | AT12: =AP12-AP11 -> 0 | AU12: =AT12/(AC12-AC11) -> #DIV/0!
Q13: =IFERROR(__xludf.DUMMYFUNCTION("""COMPUTED_VALUE"""),"ORCL") -> ORCL | R13: =IFERROR(__xludf.DUMMYFUNCTION("""COMPUTED_VALUE"""),"Oracle Corporation") -> Oracle Corporation | S13: =IFERROR(__xludf.DUMMYFUNCTION("""COMPUTED_VALUE"""),8947.942170000002) -> 8947.9422 | T13: =IFERROR(__xludf.DUMMYFUNCTION("""COMPUTED_VALUE"""),7043.978490000001) -> 7043.9785 | U13: =IFERROR(__xludf.DUMMYFUNCTION("""COMPUTED_VALUE"""),4.0) -> 4 | V13: =IFERROR(__xludf.DUMMYFUNCTION("""COMPUTED_VALUE"""),-243.84000000000003) -> -243.84 | W13: =IFERROR(__xludf.DUMMYFUNCTION("""COMPUTED_VALUE"""),-0.21278229606618035) -> -0.2127823 | X13: =IFERROR(__xludf.DUMMYFUNCTION("""COMPUTED_VALUE"""),35791.76868000001) -> 35791.769 | Y13: =IFERROR(__xludf.DUMMYFUNCTION("""COMPUTED_VALUE"""),28175.913960000005) -> 28175.914 | AP13: =sum(AD13:AM13) -> 0 | AQ13: =sum(AD13:AG13)+sum(AJ13:AL13) -> 0 | AR13: =AH13 | AS13: =AI13+AM13 -> 0 | AT13: =AP13-AP12 -> 0 | AU13: =AT13/(AC13-AC12) -> #DIV/0!
Q14: =IFERROR(__xludf.DUMMYFUNCTION("""COMPUTED_VALUE"""),"AAPL") -> AAPL | R14: =IFERROR(__xludf.DUMMYFUNCTION("""COMPUTED_VALUE"""),"Apple Inc.") -> Apple Inc. | S14: =IFERROR(__xludf.DUMMYFUNCTION("""COMPUTED_VALUE"""),7959.2771715) -> 7959.2772 | T14: =IFERROR(__xludf.DUMMYFUNCTION("""COMPUTED_VALUE"""),8387.934480000002) -> 8387.9345 | U14: =IFERROR(__xludf.DUMMYFUNCTION("""COMPUTED_VALUE"""),4.0) -> 4 | V14: =IFERROR(__xludf.DUMMYFUNCTION("""COMPUTED_VALUE"""),54.89800000000014) -> 54.898 | W14: =IFERROR(__xludf.DUMMYFUNCTION("""COMPUTED_VALUE"""),0.05385631122822384) -> 0.053856311 | X14: =IFERROR(__xludf.DUMMYFUNCTION("""COMPUTED_VALUE"""),31837.108686) -> 31837.109 | Y14: =IFERROR(__xludf.DUMMYFUNCTION("""COMPUTED_VALUE"""),33551.73792000001) -> 33551.738 | AP14: =sum(AD14:AM14) -> 0 | AQ14: =sum(AD14:AG14)+sum(AJ14:AL14) -> 0 | AR14: =AH14 | AS14: =AI14+AM14 -> 0 | AT14: =AP14-AP13 -> 0 | AU14: =AT14/(AC14-AC13) -> #DIV/0!
Q15: =IFERROR(__xludf.DUMMYFUNCTION("""COMPUTED_VALUE"""),"AMZN") -> AMZN | R15: =IFERROR(__xludf.DUMMYFUNCTION("""COMPUTED_VALUE"""),"Amazon.com, Inc.") -> Amazon.com, Inc. | S15: =IFERROR(__xludf.DUMMYFUNCTION("""COMPUTED_VALUE"""),6404.460505714287) -> 6404.4605 | T15: =IFERROR(__xludf.DUMMYFUNCTION("""COMPUTED_VALUE"""),6955.27677) -> 6955.2768 | U15: =IFERROR(__xludf.DUMMYFUNCTION("""COMPUTED_VALUE"""),3.5) -> 3.5 | V15: =IFERROR(__xludf.DUMMYFUNCTION("""COMPUTED_VALUE"""),61.72499999999991) -> 61.725 | W15: =IFERROR(__xludf.DUMMYFUNCTION("""COMPUTED_VALUE"""),0.08600509969485419) -> 0.0860051 | X15: =IFERROR(__xludf.DUMMYFUNCTION("""COMPUTED_VALUE"""),22415.611770000003) -> 22415.612 | Y15: =IFERROR(__xludf.DUMMYFUNCTION("""COMPUTED_VALUE"""),24343.468695000003) -> 24343.469 | AP15: =sum(AD15:AM15) -> 0 | AQ15: =sum(AD15:AG15)+sum(AJ15:AL15) -> 0 | AR15: =AH15 | AS15: =AI15+AM15 -> 0 | AT15: =AP15-AP14 -> 0 | AU15: =AT15/(AC15-AC14) -> #DIV/0!
Q16: =IFERROR(__xludf.DUMMYFUNCTION("""COMPUTED_VALUE"""),"meta") -> meta | R16: =IFERROR(__xludf.DUMMYFUNCTION("""COMPUTED_VALUE"""),"Meta Platforms, Inc.") -> Meta Platforms, Inc. | S16: =IFERROR(__xludf.DUMMYFUNCTION("""COMPUTED_VALUE"""),22261.320750000003) -> 22261.321 | T16: =IFERROR(__xludf.DUMMYFUNCTION("""COMPUTED_VALUE"""),18437.464560000004) -> 18437.465 | U16: =IFERROR(__xludf.DUMMYFUNCTION("""COMPUTED_VALUE"""),1.0) -> 1 | V16: =IFERROR(__xludf.DUMMYFUNCTION("""COMPUTED_VALUE"""),-122.42999999999995) -> -122.43 | W16: =IFERROR(__xludf.DUMMYFUNCTION("""COMPUTED_VALUE"""),-0.1717713083128726) -> -0.17177131 | X16: =IFERROR(__xludf.DUMMYFUNCTION("""COMPUTED_VALUE"""),22261.320750000003) -> 22261.321 | Y16: =IFERROR(__xludf.DUMMYFUNCTION("""COMPUTED_VALUE"""),18437.464560000004) -> 18437.465 | AP16: =sum(AD16:AM16) -> 0 | AQ16: =sum(AD16:AG16)+sum(AJ16:AL16) -> 0 | AR16: =AH16 | AS16: =AI16+AM16 -> 0 | AT16: =AP16-AP15 -> 0 | AU16: =AT16/(AC16-AC15) -> #DIV/0!
Q17: =IFERROR(__xludf.DUMMYFUNCTION("""COMPUTED_VALUE"""),"FBTC") -> FBTC | R17: =IFERROR(__xludf.DUMMYFUNCTION("""COMPUTED_VALUE"""),"Fidelity Wise Origin Bitcoin Fund") -> Fidelity Wise Origin Bitcoin Fund | S17: =IFERROR(__xludf.DUMMYFUNCTION("""COMPUTED_VALUE"""),2513.2302728571435) -> 2513.2303 | T17: =IFERROR(__xludf.DUMMYFUNCTION("""COMPUTED_VALUE"""),2433.9876900000004) -> 2433.9877 | U17: =IFERROR(__xludf.DUMMYFUNCTION("""COMPUTED_VALUE"""),7.0) -> 7 | V17: =IFERROR(__xludf.DUMMYFUNCTION("""COMPUTED_VALUE"""),-17.75999999999999) -> -17.76 | W17: =IFERROR(__xludf.DUMMYFUNCTION("""COMPUTED_VALUE"""),-0.031530172031175085) -> -0.031530172 | X17: =IFERROR(__xludf.DUMMYFUNCTION("""COMPUTED_VALUE"""),17592.611910000003) -> 17592.612 | Y17: =IFERROR(__xludf.DUMMYFUNCTION("""COMPUTED_VALUE"""),17037.91383) -> 17037.914 | AP17: =sum(AD17:AM17) -> 0 | AQ17: =sum(AD17:AG17)+sum(AJ17:AL17) -> 0 | AR17: =AH17 | AS17: =AI17+AM17 -> 0 | AT17: =AP17-AP16 -> 0 | AU17: =AT17/(AC17-AC16) -> #DIV/0!
Q18: =IFERROR(__xludf.DUMMYFUNCTION("""COMPUTED_VALUE"""),"MCD") -> MCD | R18: =IFERROR(__xludf.DUMMYFUNCTION("""COMPUTED_VALUE"""),"McDonald's Corporation") -> McDonald's Corporation | S18: =IFERROR(__xludf.DUMMYFUNCTION("""COMPUTED_VALUE"""),9043.579958475) -> 9043.58 | T18: =IFERROR(__xludf.DUMMYFUNCTION("""COMPUTED_VALUE"""),9455.478420000001) -> 9455.4784 | U18: =IFERROR(__xludf.DUMMYFUNCTION("""COMPUTED_VALUE"""),2.0) -> 2 | V18: =IFERROR(__xludf.DUMMYFUNCTION("""COMPUTED_VALUE"""),26.375850000000128) -> 26.37585 | W18: =IFERROR(__xludf.DUMMYFUNCTION("""COMPUTED_VALUE"""),0.04554595231272325) -> 0.045545952 | X18: =IFERROR(__xludf.DUMMYFUNCTION("""COMPUTED_VALUE"""),18087.15991695) -> 18087.16 | Y18: =IFERROR(__xludf.DUMMYFUNCTION("""COMPUTED_VALUE"""),18910.956840000003) -> 18910.957
Q19: =IFERROR(__xludf.DUMMYFUNCTION("""COMPUTED_VALUE"""),"LFWD") -> LFWD | R19: =IFERROR(__xludf.DUMMYFUNCTION("""COMPUTED_VALUE"""),"Lifeward Ltd.") -> Lifeward Ltd. | S19: =IFERROR(__xludf.DUMMYFUNCTION("""COMPUTED_VALUE"""),55.027020161538466) -> 55.02702 | T19: =IFERROR(__xludf.DUMMYFUNCTION("""COMPUTED_VALUE"""),17.146917000000002) -> 17.146917 | U19: =IFERROR(__xludf.DUMMYFUNCTION("""COMPUTED_VALUE"""),650.0) -> 650 | V19: =IFERROR(__xludf.DUMMYFUNCTION("""COMPUTED_VALUE"""),-788.3349999999999) -> -788.335 | W19: =IFERROR(__xludf.DUMMYFUNCTION("""COMPUTED_VALUE"""),-0.688390958666067) -> -0.68839096 | X19: =IFERROR(__xludf.DUMMYFUNCTION("""COMPUTED_VALUE"""),35767.563105) -> 35767.563 | Y19: =IFERROR(__xludf.DUMMYFUNCTION("""COMPUTED_VALUE"""),11145.496050000002) -> 11145.496
Q20: =IFERROR(__xludf.DUMMYFUNCTION("""COMPUTED_VALUE"""),"ABNB") -> ABNB | R20: =IFERROR(__xludf.DUMMYFUNCTION("""COMPUTED_VALUE"""),"Airbnb, Inc.") -> Airbnb, Inc. | S20: =IFERROR(__xludf.DUMMYFUNCTION("""COMPUTED_VALUE"""),4058.5425136500007) -> 4058.5425 | T20: =IFERROR(__xludf.DUMMYFUNCTION("""COMPUTED_VALUE"""),3574.3045200000006) -> 3574.3045 | U20: =IFERROR(__xludf.DUMMYFUNCTION("""COMPUTED_VALUE"""),3.0) -> 3 | V20: =IFERROR(__xludf.DUMMYFUNCTION("""COMPUTED_VALUE"""),-46.51215000000002) -> -46.51215 | W20: =IFERROR(__xludf.DUMMYFUNCTION("""COMPUTED_VALUE"""),-0.11931327367432373) -> -0.11931327 | X20: =IFERROR(__xludf.DUMMYFUNCTION("""COMPUTED_VALUE"""),12175.627540950001) -> 12175.628 | Y20: =IFERROR(__xludf.DUMMYFUNCTION("""COMPUTED_VALUE"""),10722.91356) -> 10722.914
Q21: =IFERROR(__xludf.DUMMYFUNCTION("""COMPUTED_VALUE"""),"TSLZ") -> TSLZ | R21: =IFERROR(__xludf.DUMMYFUNCTION("""COMPUTED_VALUE"""),"T-Rex 2X Inverse Tesla Daily Target ETF") -> T-Rex 2X Inverse Tesla Daily Target ETF | S21: =IFERROR(__xludf.DUMMYFUNCTION("""COMPUTED_VALUE"""),3157.6563) -> 3157.6563 | T21: =IFERROR(__xludf.DUMMYFUNCTION("""COMPUTED_VALUE"""),486.2978100000001) -> 486.29781 | U21: =IFERROR(__xludf.DUMMYFUNCTION("""COMPUTED_VALUE"""),5.0) -> 5 | V21: =IFERROR(__xludf.DUMMYFUNCTION("""COMPUTED_VALUE"""),-427.65) -> -427.65 | W21: =IFERROR(__xludf.DUMMYFUNCTION("""COMPUTED_VALUE"""),-0.845994065281899) -> -0.84599407 | X21: =IFERROR(__xludf.DUMMYFUNCTION("""COMPUTED_VALUE"""),15788.281500000003) -> 15788.281 | Y21: =IFERROR(__xludf.DUMMYFUNCTION("""COMPUTED_VALUE"""),2431.48905) -> 2431.4891 | AT21: 116.22 | AU21: 41051.91
Q22: =IFERROR(__xludf.DUMMYFUNCTION("""COMPUTED_VALUE"""),"1432") -> 1432 | R22: =IFERROR(__xludf.DUMMYFUNCTION("""COMPUTED_VALUE"""),"大魯閣") -> 大魯閣 | S22: =IFERROR(__xludf.DUMMYFUNCTION("""COMPUTED_VALUE"""),20.0) -> 20 | T22: =IFERROR(__xludf.DUMMYFUNCTION("""COMPUTED_VALUE"""),17.15) -> 17.15 | U22: =IFERROR(__xludf.DUMMYFUNCTION("""COMPUTED_VALUE"""),1.0) -> 1 | V22: =IFERROR(__xludf.DUMMYFUNCTION("""COMPUTED_VALUE"""),-2.8500000000000014) -> -2.85 | W22: =IFERROR(__xludf.DUMMYFUNCTION("""COMPUTED_VALUE"""),-0.14250000000000007) -> -0.1425 | X22: =IFERROR(__xludf.DUMMYFUNCTION("""COMPUTED_VALUE"""),20.0) -> 20 | Y22: =IFERROR(__xludf.DUMMYFUNCTION("""COMPUTED_VALUE"""),17.15) -> 17.15 | AT22: =AT21*J6 -> 3629.8993 | AU22: =AU21*J6 -> 1282174.3
Q23: =IFERROR(__xludf.DUMMYFUNCTION("""COMPUTED_VALUE"""),"006208") -> 006208 | R23: =IFERROR(__xludf.DUMMYFUNCTION("""COMPUTED_VALUE"""),"富邦台50") -> 富邦台50 | S23: =IFERROR(__xludf.DUMMYFUNCTION("""COMPUTED_VALUE"""),116.44382352941177) -> 116.44382 | T23: =IFERROR(__xludf.DUMMYFUNCTION("""COMPUTED_VALUE"""),141.55) -> 141.55 | U23: =IFERROR(__xludf.DUMMYFUNCTION("""COMPUTED_VALUE"""),34.0) -> 34 | V23: =IFERROR(__xludf.DUMMYFUNCTION("""COMPUTED_VALUE"""),853.6100000000006) -> 853.61 | W23: =IFERROR(__xludf.DUMMYFUNCTION("""COMPUTED_VALUE"""),0.21560762700519578) -> 0.21560763 | X23: =IFERROR(__xludf.DUMMYFUNCTION("""COMPUTED_VALUE"""),3959.09) -> 3959.09 | Y23: =IFERROR(__xludf.DUMMYFUNCTION("""COMPUTED_VALUE"""),4812.700000000001) -> 4812.7
Q24: =IFERROR(__xludf.DUMMYFUNCTION("""COMPUTED_VALUE"""),"009800") -> 009800 | R24: =IFERROR(__xludf.DUMMYFUNCTION("""COMPUTED_VALUE"""),"中信NASDAQ") -> 中信NASDAQ | S24: =IFERROR(__xludf.DUMMYFUNCTION("""COMPUTED_VALUE"""),10.008461538461539) -> 10.008462 | T24: =IFERROR(__xludf.DUMMYFUNCTION("""COMPUTED_VALUE"""),10.92) -> 10.92 | U24: =IFERROR(__xludf.DUMMYFUNCTION("""COMPUTED_VALUE"""),1300.0) -> 1300 | V24: =IFERROR(__xludf.DUMMYFUNCTION("""COMPUTED_VALUE"""),1185.0) -> 1185 | W24: =IFERROR(__xludf.DUMMYFUNCTION("""COMPUTED_VALUE"""),0.09107678118515103) -> 0.091076781 | X24: =IFERROR(__xludf.DUMMYFUNCTION("""COMPUTED_VALUE"""),13011.0) -> 13011 | Y24: =IFERROR(__xludf.DUMMYFUNCTION("""COMPUTED_VALUE"""),14196.0) -> 14196
Q25: =IFERROR(__xludf.DUMMYFUNCTION("""COMPUTED_VALUE"""),"2330") -> 2330 | R25: =IFERROR(__xludf.DUMMYFUNCTION("""COMPUTED_VALUE"""),"台積電") -> 台積電 | S25: =IFERROR(__xludf.DUMMYFUNCTION("""COMPUTED_VALUE"""),1462.0714285714287) -> 1462.0714 | T25: =IFERROR(__xludf.DUMMYFUNCTION("""COMPUTED_VALUE"""),1455.0) -> 1455 | U25: =IFERROR(__xludf.DUMMYFUNCTION("""COMPUTED_VALUE"""),42.0) -> 42 | V25: =IFERROR(__xludf.DUMMYFUNCTION("""COMPUTED_VALUE"""),-297.0) -> -297 | W25: =IFERROR(__xludf.DUMMYFUNCTION("""COMPUTED_VALUE"""),-0.004836582148614979) -> -0.0048365821 | X25: =IFERROR(__xludf.DUMMYFUNCTION("""COMPUTED_VALUE"""),61407.0) -> 61407 | Y25: =IFERROR(__xludf.DUMMYFUNCTION("""COMPUTED_VALUE"""),61110.0) -> 61110
Q26: =IFERROR(__xludf.DUMMYFUNCTION("""COMPUTED_VALUE"""),"0050") -> 0050 | R26: =IFERROR(__xludf.DUMMYFUNCTION("""COMPUTED_VALUE"""),"元大台灣50") -> 元大台灣50 | S26: =IFERROR(__xludf.DUMMYFUNCTION("""COMPUTED_VALUE"""),45.716345936794575) -> 45.716346 | T26: =IFERROR(__xludf.DUMMYFUNCTION("""COMPUTED_VALUE"""),61.9) -> 61.9 | U26: =IFERROR(__xludf.DUMMYFUNCTION("""COMPUTED_VALUE"""),3544.0) -> 3544 | V26: =IFERROR(__xludf.DUMMYFUNCTION("""COMPUTED_VALUE"""),57354.870000000024) -> 57354.87 | W26: =IFERROR(__xludf.DUMMYFUNCTION("""COMPUTED_VALUE"""),0.35400147871792376) -> 0.35400148 | X26: =IFERROR(__xludf.DUMMYFUNCTION("""COMPUTED_VALUE"""),162018.72999999998) -> 162018.73 | Y26: =IFERROR(__xludf.DUMMYFUNCTION("""COMPUTED_VALUE"""),219373.6) -> 219373.6

Sheet record
A1: 日期 | B1: 台股市值 | C1: 台股成本 | D1: 台股損益 | E1: 台股損益率 | F1: 美股(TWD) 市值 | G1: 美股(TWD) 成本 | H1: 美股(TWD) 損益 | I1: 美股(TWD) 損益率 | J1: 美股(USD) 市值 | K1: 美股(USD) 成本 | L1: 美股(USD) 損益 | M1: 美股(USD) 損益率 | N1: 總市值 | O1: 總成本 | P1: 總損益 | Q1: 總損益率
A2: 45709 | B2: 102112.35 | C2: 100701.09 | D2: 1411.26 | E2: 0.014014347 | F2: 533777.49 | G2: 534142.39 | H2: -364.8978 | I2: -0.00068314706 | J2: 16290.841 | K2: 16255.564 | L2: 35.276687 | M2: 0.0021701299 | N2: 635889.84 | O2: 634843.48 | P2: 1046.3622 | Q2: 0.0016482208
A3: 45710 | B3: 102112.35 | C3: 100701.09 | D3: 1411.26 | E3: 0.014014347 | F3: 555166.72 | G3: 567339.15 | H3: -12172.428 | I3: -0.021455293 | J3: 16932.009 | K3: 17267.165 | L3: -335.15539 | M3: -0.019409984 | N3: 657279.07 | O3: 668040.24 | P3: -10761.168 | Q3: -0.016108562
A4: 45713 | B4: 135785 | C4: 135241.57 | D4: 543.43 | E4: 0.0040182172 | F4: 656080.85 | G4: 677789.26 | H4: -21708.412 | I4: -0.032028262 | J4: 20051.677 | K4: 20631.019 | L4: -579.34156 | M4: -0.028081093 | N4: 791865.85 | O4: 813030.83 | P4: -21164.982 | Q4: -0.026032201
A5: 45714 | B5: 144532 | C5: 144949.07 | D5: -417.07 | E5: -0.0028773555 | F5: 701260.85 | G5: 734743.31 | H5: -33482.458 | I5: -0.04557028 | J5: 21381.668 | K5: 22365.604 | L5: -983.93589 | M5: -0.043993263 | N5: 845792.85 | O5: 879692.38 | P5: -33899.528 | Q5: -0.038535662
A6: 45715 | B6: 144532 | C6: 144949.07 | D6: -417.07 | E6: -0.0028773555 | F6: 723592.29 | G6: 755499.13 | H6: -31906.846 | I6: -0.042232802 | J6: 22076.625 | K6: 23015.877 | L6: -939.25204 | M6: -0.040808875 | N6: 868124.29 | O6: 900448.2 | P6: -32323.916 | Q6: -0.035897585
A7: 45716 | B7: 143051.6 | C7: 144949.07 | D7: -1897.47 | E7: -0.013090598 | F7: 711121.87 | G7: 758287.3 | H7: -47165.43 | I7: -0.062199948 | J7: 21583.487 | K7: 23100.877 | L7: -1517.3895 | M7: -0.065685364 | N7: 854173.47 | O7: 903236.37 | P7: -49062.9 | Q7: -0.054319004
A8: 45717 | B8: 143051.6 | C8: 144949.07 | D8: -1897.47 | E8: -0.013090598 | F8: 750796.78 | G8: 784044.05 | H8: -33247.275 | I8: -0.042404855 | J8: 22806.706 | K8: 23886.097 | L8: -1079.3905 | M8: -0.045189069 | N8: 893848.38 | O8: 928993.12 | P8: -35144.745 | Q8: -0.037831006
A9: 45720 | B9: 173204.1 | C9: 177918.82 | D9: -4714.72 | E9: -0.026499276 | F9: 789313.09 | G9: 841249.6 | H9: -51936.517 | I9: -0.061737345 | J9: 23989.316 | K9: 25630.065 | L9: -1640.7483 | M9: -0.06401655 | N9: 962517.19 | O9: 1019168.4 | P9: -56651.237 | Q9: -0.055585746
A10: 45721 | B10: 173468.2 | C10: 177918.82 | D10: -4450.62 | E10: -0.025014892 | F10: 812048.58 | G10: 871269.27 | H10: -59220.689 | I10: -0.067970593 | J10: 24732.319 | K10: 26545.244 | L10: -1812.9254 | M10: -0.068295676 | N10: 985516.78 | O10: 1049188.1 | P10: -63671.309 | Q10: -0.060686268
A11: 45722 | B11: 173843.4 | C11: 177918.82 | D11: -4075.42 | E11: -0.022906065 | F11: 827245.92 | G11: 871269.27 | H11: -44023.355 | I11: -0.050527841 | J11: 25194.651 | K11: 26545.244 | L11: -1350.5927 | M11: -0.050878895 | N11: 1001089.3 | O11: 1049188.1 | P11: -48098.775 | Q11: -0.045843806
A12: 45723 | B12: 173057.8 | C12: 177918.82 | D12: -4861.02 | E12: -0.027321562 | F12: 822706.21 | G12: 898986.45 | H12: -76280.246 | I12: -0.084851385 | J12: 25025.439 | K12: 27390.23 | L12: -2364.7902 | M12: -0.086336999 | N12: 995764.01 | O12: 1076905.3 | P12: -81141.266 | Q12: -0.075346707
A13: 45724 | B13: 171393.8 | C13: 177918.82 | D13: -6525.02 | E13: -0.036674142 | F13: 901624.87 | G13: 979752.31 | H13: -78127.446 | I13: -0.079742038 | J13: 27453.409 | K13: 29852.457 | L13: -2399.0474 | M13: -0.080363483 | N13: 1073018.7 | O13: 1157671.1 | P13: -84652.466 | Q13: -0.073123069
... A27: 45744 | B27: 185634.71 | C27: 196109.44 | D27: -10474.73 | E27: -0.053412676 | F27: 958791.14 | G27: 1028996.2 | H27: -70205.017 | I27: -0.068226704 | J27: 28942.808 | K27: 31336.236 | L27: -2393.4279 | M27: -0.076378923 | N27: 1144425.9 | O27: 1225105.6 | P27: -80679.747 | Q27: -0.065855341
A28: 45745 | B28: 183930.07 | C28: 196109.44 | D28: -12179.37 | E28: -0.062104965 | F28: 935684.49 | G28: 1028996.2 | H28: -93311.667 | I28: -0.09068223 | J28: 28206.63 | K28: 31336.236 | L28: -3129.6055 | M28: -0.099871777 | N28: 1119614.6 | O28: 1225105.6 | P28: -105491.04 | Q28: -0.086107709 | Z28: 3453
A29: 45748 | B29: 189640.9 | C29: 208302.94 | D29: -18662.04 | E29: -0.089590862 | F29: 978565.34 | G29: 1073009.3 | H29: -94443.966 | I29: -0.088017844 | J29: 29427.881 | K29: 32677.086 | L29: -3249.2042 | M29: -0.099433722 | N29: 1168206.2 | O29: 1281312.2 | P29: -113106.01 | Q29: -0.08827357
A30: 45749 | B30: 193240.24 | C30: 208302.94 | D30: -15062.7 | E30: -0.072311509 | F30: 991575.17 | G30: 1073009.3 | H30: -81434.13 | I30: -0.075893219 | J30: 29848.931 | K30: 32677.086 | L30: -2828.1542 | M30: -0.086548546 | N30: 1184815.4 | O30: 1281312.2 | P30: -96496.83 | Q30: -0.07531094
A31: 45751 | B31: 192964.36 | C31: 208302.94 | D31: -15338.58 | E31: -0.073635927 | F31: 964816.32 | G31: 1085638.3 | H31: -120822 | I31: -0.1112912 | J31: 29131.367 | K31: 33061.826 | L31: -3930.4581 | M31: -0.11888207 | N31: 1157780.7 | O31: 1293941.3 | P31: -136160.58 | Q31: -0.10522933
A32: 45752 | B32: 192964.36 | C32: 208302.94 | D32: -15338.58 | E32: -0.073635927 | F32: 898441.72 | G32: 1085638.3 | H32: -187196.6 | I32: -0.17242999 | J32: 27127.273 | K32: 33061.826 | L32: -5934.5525 | M32: -0.17949863 | N32: 1091406.1 | O32: 1293941.3 | P32: -202535.18 | Q32: -0.15652579
A33: 45755 | B33: 173197.4 | C33: 208302.94 | D33: -35105.54 | E33: -0.16853118 | F33: 891693.8 | G33: 1085638.3 | H33: -193944.52 | I33: -0.17864561 | J33: 27023.153 | K33: 33061.826 | L33: -6038.6723 | M33: -0.18264788 | N33: 1064891.2 | O33: 1293941.3 | P33: -229050.06 | Q33: -0.17701736
A34: 45756 | B34: 168578.62 | C34: 208302.94 | D34: -39724.32 | E34: -0.19070456 | F34: 876285.91 | G34: 1085638.3 | H34: -209352.41 | I34: -0.19283808 | J34: 26475.261 | K34: 33061.826 | L34: -6586.5644 | M34: -0.19921962 | N34: 1044864.5 | O34: 1293941.3 | P34: -249076.73 | Q34: -0.19249462
A35: 45757 | B35: 160739.5 | C35: 208302.94 | D35: -47563.44 | E35: -0.22833782 | F35: 1011086 | G35: 1125158.1 | H35: -114072.05 | I35: -0.10138313 | J35: 31020.999 | K35: 34265.786 | L35: -3244.7866 | M35: -0.094694652 | N35: 1171825.5 | O35: 1333461 | P35: -161635.49 | Q35: -0.12121501
A36: 45758 | B36: 217314.14 | C36: 246544.44 | D36: -29230.3 | E36: -0.11855996 | F36: 971212.32 | G36: 1124649.3 | H36: -153436.98 | I36: -0.13643096 | J36: 29609.777 | K36: 34250.286 | L36: -4640.5085 | M36: -0.13548817 | N36: 1188526.5 | O36: 1371193.7 | P36: -182667.28 | Q36: -0.1332177
A37: 45760 | B37: 221392.54 | C37: 246544.44 | D37: -25151.9 | E37: -0.10201771 | F37: 969370.28 | G37: 1124649.3 | H37: -155279.01 | I37: -0.13806883 | J37: 29994.749 | K37: 34250.286 | L37: -4255.5371 | M37: -0.12424822 | N37: 1190762.8 | O37: 1371193.7 | P37: -180430.91 | Q37: -0.13158674
A38: 45762 | B38: 220761.46 | C38: 246544.44 | D38: -25782.98 | E38: -0.10457741 | F38: 976645.48 | G38: 1124649.3 | H38: -148003.82 | I38: -0.13159997 | J38: 30148.499 | K38: 34250.286 | L38: -4101.7866 | M38: -0.11975919 | N38: 1197406.9 | O38: 1371193.7 | P38: -173786.8 | Q38: -0.12674124
A39: 45763 | B39: 222875.01 | C39: 246544.44 | D39: -23669.43 | E39: -0.09600472 | F39: 982663.05 | G39: 1124649.3 | H39: -141986.24 | I39: -0.12624935 | J39: 30218.027 | K39: 34250.286 | L39: -4032.2583 | M39: -0.11772919 | N39: 1205538.1 | O39: 1371193.7 | P39: -165655.67 | Q39: -0.12081128
A40: 45764 | B40: 219009.92 | C40: 246544.44 | D40: -27534.52 | E40: -0.11168177 | F40: 950167.24 | G40: 1124649.3 | H40: -174482.05 | I40: -0.15514352 | J40: 29319.463 | K40: 34250.286 | L40: -4930.823 | M40: -0.14396443 | N40: 1169177.2 | O40: 1371193.7 | P40: -202016.57 | Q40: -0.14732898
... A190: 45981 | B190: 289885.5 | C190: 240415.82 | D190: 49469.68 | E190: 0.20576716 | F190: 1307924.2 | G190: 1111114.9 | H190: 196809.33 | I190: 0.1771278 | J190: 41898.221 | K190: 33937.574 | L190: 7960.6467 | M190: 0.23456735 | N190: 1597809.7 | O190: 1351530.7 | P190: 246279.01 | Q190: 0.18222229

Sheet 美股庫存
A1: 股票代號 | B1: 股票名稱 | C1: 平均成本 | D1: 現價 | E1: 持有股數 | F1: 損益 | G1: 損益率 | H1: 總投資成本 | I1: 市值(USD) | J1: 成本(TWD) | K1: 今日走勢$ | L1: 今日走勢 | M1: 今日損益 | N1: 股票類別
A2: TSLA | B2: =IFERROR(__xludf.DUMMYFUNCTION("INDEX(IMPORTXML(""https://tw.stock.yahoo.com/quote/"" & A2, ""//h1""), 2)"),"Tesla, Inc.") -> Tesla, Inc. | C2: =H2/E2 -> 292.3624 | D2: =getStockPrice(A2) -> 403.99 | E2: =SUMIFS('美股購買'!E:E, '美股購買'!D:D, A2, '美股購買'!B:B, "買進")-SUMIFS('美股購買'!E:E, '美股購買'!D:D, A2, '美股購買'!B:B, "賣出") -> 18.5 | F2: =I2-H2 -> 2065.1107 | G2: =F2/H2 -> 0.38181245 | H2: =SUMIFS('美股購買'!$G:$G, '美股購買'!$D:$D, $A2, '美股購買'!B:B, "買進")-SUMIFS('美股購買'!$I:$I, '美股購買'!$D:$D, $A2, '美股購買'!B:B, "賣出") -> 5408.7043 | I2: =E2*D2 -> 7473.815 | J2: =SUMIFS('美股購買'!$H:$H, '美股購買'!$D:$D, $A2, '美股購買'!B:B, "買進")-SUMIFS('美股購買'!$J:J, '美股購買'!$D:$D, $A2, '美股購買'!B:B, "賣出") -> 177553.77 | K2: =IFERROR(__xludf.DUMMYFUNCTION("IFERROR(GOOGLEFINANCE(A2, ""price"") - getYahooStockClose(A2), 0)"),2.740000000000009) -> 2.74 | L2: =iferror(K2/getYahooStockClose(A2), 0) -> 0.0068286604 | M2: =K2*E2 -> 50.69 | N2: 科技
A3: TSLL | B3: =IFERROR(__xludf.DUMMYFUNCTION("INDEX(IMPORTXML(""https://tw.stock.yahoo.com/quote/"" & A3, ""//h1""), 2)"),"Direxion Daily TSLA Bull 2X Shares") -> Direxion Daily TSLA Bull 2X Shares | C3: =H3/E3 -> 11.292541 | D3: =getStockPrice(A3) -> 16.51 | E3: =SUMIFS('美股購買'!E:E, '美股購買'!D:D, A3, '美股購買'!B:B, "買進")-SUMIFS('美股購買'!E:E, '美股購買'!D:D, A3, '美股購買'!B:B, "賣出") -> 98 | F3: =I3-H3 -> 511.311 | G3: =F3/H3 -> 0.46202704 | H3: =SUMIFS('美股購買'!$G:$G, '美股購買'!$D:$D, $A3, '美股購買'!B:B, "買進")-SUMIFS('美股購買'!$I:$I, '美股購買'!$D:$D, $A3, '美股購買'!B:B, "賣出") -> 1106.669 | I3: =E3*D3 -> 1617.98 | J3: =SUMIFS('美股購買'!$H:$H, '美股購買'!$D:$D, $A3, '美股購買'!B:B, "買進")-SUMIFS('美股購買'!$J:J, '美股購買'!$D:$D, $A3, '美股購買'!B:B, "賣出") -> 36329.11 | K3: =IFERROR(__xludf.DUMMYFUNCTION("IFERROR(GOOGLEFINANCE(A3, ""price"") - getYahooStockClose(A3), 0)"),0.2199990844726578) -> 0.21999908 | L3: =iferror(K3/getYahooStockClose(A3), 0) -> 0.013505161 | M3: =K3*E3 -> 21.55991 | N3: 科技
A4: QQQ | B4: =IFERROR(__xludf.DUMMYFUNCTION("INDEX(IMPORTXML(""https://tw.stock.yahoo.com/quote/"" & A4, ""//h1""), 2)"),"Invesco QQQ Trust") -> Invesco QQQ Trust | C4: =H4/E4 -> 520.03626 | D4: =getStockPrice(A4) -> 599.87 | E4: =SUMIFS('美股購買'!E:E, '美股購買'!D:D, A4, '美股購買'!B:B, "買進")-SUMIFS('美股購買'!E:E, '美股購買'!D:D, A4, '美股購買'!B:B, "賣出") -> 11.00795 | F4: =I4-H4 -> 878.80585 | G4: =F4/H4 -> 0.15351572 | H4: =SUMIFS('美股購買'!$G:$G, '美股購買'!$D:$D, $A4, '美股購買'!B:B, "買進")-SUMIFS('美股購買'!$I:$I, '美股購買'!$D:$D, $A4, '美股購買'!B:B, "賣出") -> 5724.5331 | I4: =E4*D4 -> 6603.339 | J4: =SUMIFS('美股購買'!$H:$H, '美股購買'!$D:$D, $A4, '美股購買'!B:B, "買進")-SUMIFS('美股購買'!$J:J, '美股購買'!$D:$D, $A4, '美股購買'!B:B, "賣出") -> 187921.77 | K4: =IFERROR(__xludf.DUMMYFUNCTION("IFERROR(GOOGLEFINANCE(A4, ""price"") - getYahooStockClose(A4), 0)"),3.5600024414062545) -> 3.5600024 | L4: =iferror(K4/getYahooStockClose(A4), 0) -> 0.0059700533 | M4: =K4*E4 -> 39.188329 | N4: 大盤
A5: VOO | B5: =IFERROR(__xludf.DUMMYFUNCTION("INDEX(IMPORTXML(""https://tw.stock.yahoo.com/quote/"" & A5, ""//h1""), 2)"),"Vanguard S&P 500 ETF") -> Vanguard S&P 500 ETF | C5: =H5/E5 -> 543.5785 | D5: =getStockPrice(A5) -> 609.2 | E5: =SUMIFS('美股購買'!E:E, '美股購買'!D:D, A5, '美股購買'!B:B, "買進")-SUMIFS('美股購買'!E:E, '美股購買'!D:D, A5, '美股購買'!B:B, "賣出") -> 7.06427 | F5: =I5-H5 -> 463.56797 | G5: =F5/H5 -> 0.12072129 | H5: =SUMIFS('美股購買'!$G:$G, '美股購買'!$D:$D, $A5, '美股購買'!B:B, "買進")-SUMIFS('美股購買'!$I:$I, '美股購買'!$D:$D, $A5, '美股購買'!B:B, "賣出") -> 3839.9853 | I5: =E5*D5 -> 4303.5533 | J5: =SUMIFS('美股購買'!$H:$H, '美股購買'!$D:$D, $A5, '美股購買'!B:B, "買進")-SUMIFS('美股購買'!$J:J, '美股購買'!$D:$D, $A5, '美股購買'!B:B, "賣出") -> 126056.89 | K5: =IFERROR(__xludf.DUMMYFUNCTION("IFERROR(GOOGLEFINANCE(A5, ""price"") - getYahooStockClose(A5), 0)"),2.2000000000000455) -> 2.2 | L5: =iferror(K5/getYahooStockClose(A5), 0) -> 0.0036243822 | M5: =K5*E5 -> 15.541394 | N5: 大盤
A6: NVDA | B6: =IFERROR(__xludf.DUMMYFUNCTION("INDEX(IMPORTXML(""https://tw.stock.yahoo.com/quote/"" & A6, ""//h1""), 2)"),"NVIDIA Corporation") -> NVIDIA Corporation | C6: =H6/E6 -> 141.03393 | D6: =getStockPrice(A6) -> 186.52 | E6: =SUMIFS('美股購買'!E:E, '美股購買'!D:D, A6, '美股購買'!B:B, "買進")-SUMIFS('美股購買'!E:E, '美股購買'!D:D, A6, '美股購買'!B:B, "賣出") -> 17 | F6: =I6-H6 -> 773.2632 | G6: =F6/H6 -> 0.32251864 | H6: =SUMIFS('美股購買'!$G:$G, '美股購買'!$D:$D, $A6, '美股購買'!B:B, "買進")-SUMIFS('美股購買'!$I:$I, '美股購買'!$D:$D, $A6, '美股購買'!B:B, "賣出") -> 2397.5768 | I6: =E6*D6 -> 3170.84 | J6: =SUMIFS('美股購買'!$H:$H, '美股購買'!$D:$D, $A6, '美股購買'!B:B, "買進")-SUMIFS('美股購買'!$J:J, '美股購買'!$D:$D, $A6, '美股購買'!B:B, "賣出") -> 79008.38 | K6: =IFERROR(__xludf.DUMMYFUNCTION("IFERROR(GOOGLEFINANCE(A6, ""price"") - getYahooStockClose(A6), 0)"),5.159999389648448) -> 5.1599994 | L6: =iferror(K6/getYahooStockClose(A6), 0) -> 0.028451695 | M6: =K6*E6 -> 87.71999 | N6: 科技 | V6: 總市值 | W6: 總損益 | X6: 今日損益 | Z6: =IFERROR(__xludf.DUMMYFUNCTION("QUERY(A:N, ""SELECT N, SUM(I) WHERE N IS NOT NULL GROUP BY N ORDER BY SUM(I) DESC"", 1)"),"股票類別") -> 股票類別 | AA6: =IFERROR(__xludf.DUMMYFUNCTION("""COMPUTED_VALUE"""),"sum 市值(USD)") -> sum 市值(USD)
A7: RDDT | B7: =IFERROR(__xludf.DUMMYFUNCTION("INDEX(IMPORTXML(""https://tw.stock.yahoo.com/quote/"" & A7, ""//h1""), 2)"),"Reddit, Inc.") -> Reddit, Inc. | C7: =H7/E7 -> 155.69198 | D7: =getStockPrice(A7) -> 187.78 | E7: =SUMIFS('美股購買'!E:E, '美股購買'!D:D, A7, '美股購買'!B:B, "買進")-SUMIFS('美股購買'!E:E, '美股購買'!D:D, A7, '美股購買'!B:B, "賣出") -> 13.87582 | F7: =I7-H7 -> 445.24764 | G7: =F7/H7 -> 0.20609941 | H7: =SUMIFS('美股購買'!$G:$G, '美股購買'!$D:$D, $A7, '美股購買'!B:B, "買進")-SUMIFS('美股購買'!$I:$I, '美股購買'!$D:$D, $A7, '美股購買'!B:B, "賣出") -> 2160.3538 | I7: =E7*D7 -> 2605.6015 | J7: =SUMIFS('美股購買'!$H:$H, '美股購買'!$D:$D, $A7, '美股購買'!B:B, "買進")-SUMIFS('美股購買'!$J:J, '美股購買'!$D:$D, $A7, '美股購買'!B:B, "賣出") -> 70918.885 | K7: =IFERROR(__xludf.DUMMYFUNCTION("IFERROR(GOOGLEFINANCE(A7, ""price"") - getYahooStockClose(A7), 0)"),2.089997558593751) -> 2.0899976 | L7: =iferror(K7/getYahooStockClose(A7), 0) -> 0.011255305 | M7: =K7*E7 -> 29.00043 | N7: 科技 | V7: =SUM(I:I) -> 38668.659 | W7: =V7-V9 -> 4731.085 | X7: =SUMPRODUCT(E2:E999, K2:K999) -> -455.63703 | Z7: =IFERROR(__xludf.DUMMYFUNCTION("""COMPUTED_VALUE"""),"科技") -> 科技 | AA7: =IFERROR(__xludf.DUMMYFUNCTION("""COMPUTED_VALUE"""),21620.8764796) -> 21620.876
A8: COST | B8: =IFERROR(__xludf.DUMMYFUNCTION("INDEX(IMPORTXML(""https://tw.stock.yahoo.com/quote/"" & A8, ""//h1""), 2)"),"Costco Wholesale Corporation") -> Costco Wholesale Corporation | C8: =H8/E8 -> 1019.0454 | D8: =getStockPrice(A8) -> 890.6 | E8: =SUMIFS('美股購買'!E:E, '美股購買'!D:D, A8, '美股購買'!B:B, "買進")-SUMIFS('美股購買'!E:E, '美股購買'!D:D, A8, '美股購買'!B:B, "賣出") -> 2.4 | F8: =I8-H8 -> -308.269 | G8: =F8/H8 -> -0.12604484 | H8: =SUMIFS('美股購買'!$G:$G, '美股購買'!$D:$D, $A8, '美股購買'!B:B, "買進")-SUMIFS('美股購買'!$I:$I, '美股購買'!$D:$D, $A8, '美股購買'!B:B, "賣出") -> 2445.709 | I8: =E8*D8 -> 2137.44 | J8: =SUMIFS('美股購買'!$H:$H, '美股購買'!$D:$D, $A8, '美股購買'!B:B, "買進")-SUMIFS('美股購買'!$J:J, '美股購買'!$D:$D, $A8, '美股購買'!B:B, "賣出") -> 80286.365 | K8: =IFERROR(__xludf.DUMMYFUNCTION("IFERROR(GOOGLEFINANCE(A8, ""price"") - getYahooStockClose(A8), 0)"),-4.480017089843727) -> -4.4800171 | L8: =iferror(K8/getYahooStockClose(A8), 0) -> -0.0050051582 | M8: =K8*E8 -> -10.752041 | N8: 必須消費 | V8: 總成本 | W8: 總損益率 | X8: 今日損益率 | Z8: =IFERROR(__xludf.DUMMYFUNCTION("""COMPUTED_VALUE"""),"大盤") -> 大盤 | AA8: =IFERROR(__xludf.DUMMYFUNCTION("""COMPUTED_VALUE"""),12258.7922505) -> 12258.792
A9: PLTR | B9: =IFERROR(__xludf.DUMMYFUNCTION("INDEX(IMPORTXML(""https://tw.stock.yahoo.com/quote/"" & A9, ""//h1""), 2)"),"Palantir Technologies Inc.") -> Palantir Technologies Inc. | C9: =H9/E9 -> 111.76 | D9: =getStockPrice(A9) -> 165.42 | E9: =SUMIFS('美股購買'!E:E, '美股購買'!D:D, A9, '美股購買'!B:B, "買進")-SUMIFS('美股購買'!E:E, '美股購買'!D:D, A9, '美股購買'!B:B, "賣出") -> 10 | F9: =I9-H9 -> 536.6 | G9: =F9/H9 -> 0.48013601 | H9: =SUMIFS('美股購買'!$G:$G, '美股購買'!$D:$D, $A9, '美股購買'!B:B, "買進")-SUMIFS('美股購買'!$I:$I, '美股購買'!$D:$D, $A9, '美股購買'!B:B, "賣出") -> 1117.6 | I9: =E9*D9 -> 1654.2 | J9: =SUMIFS('美股購買'!$H:$H, '美股購買'!$D:$D, $A9, '美股購買'!B:B, "買進")-SUMIFS('美股購買'!$J:J, '美股購買'!$D:$D, $A9, '美股購買'!B:B, "賣出") -> 36687.947 | K9: =IFERROR(__xludf.DUMMYFUNCTION("IFERROR(GOOGLEFINANCE(A9, ""price"") - getYahooStockClose(A9), 0)"),-1.9100018310547) -> -1.9100018 | L9: =iferror(K9/getYahooStockClose(A9), 0) -> -0.011414581 | M9: =K9*E9 -> -19.100018 | N9: 科技 | V9: =sum(H:H) -> 33937.574 | W9: =W7/V9 -> 0.13940552 | X9: =X7/V7 -> -0.011783109 | Z9: =IFERROR(__xludf.DUMMYFUNCTION("""COMPUTED_VALUE"""),"必須消費") -> 必須消費 | AA9: =IFERROR(__xludf.DUMMYFUNCTION("""COMPUTED_VALUE"""),3086.2400000000007) -> 3086.24
A10: QLD | B10: =IFERROR(__xludf.DUMMYFUNCTION("INDEX(IMPORTXML(""https://tw.stock.yahoo.com/quote/"" & A10, ""//h1""), 2)"),"ProShares Ultra QQQ") -> ProShares Ultra QQQ | C10: =H10/E10 -> 100.16294 | D10: =getStockPrice(A10) -> 135.19 | E10: =SUMIFS('美股購買'!E:E, '美股購買'!D:D, A10, '美股購買'!B:B, "買進")-SUMIFS('美股購買'!E:E, '美股購買'!D:D, A10, '美股購買'!B:B, "賣出") -> 10 | F10: =I10-H10 -> 350.27063 | G10: =F10/H10 -> 0.34970084 | H10: =SUMIFS('美股購買'!$G:$G, '美股購買'!$D:$D, $A10, '美股購買'!B:B, "買進")-SUMIFS('美股購買'!$I:$I, '美股購買'!$D:$D, $A10, '美股購買'!B:B, "賣出") -> 1001.6294 | I10: =E10*D10 -> 1351.9 | J10: =SUMIFS('美股購買'!$H:$H, '美股購買'!$D:$D, $A10, '美股購買'!B:B, "買進")-SUMIFS('美股購買'!$J:J, '美股購買'!$D:$D, $A10, '美股購買'!B:B, "賣出") -> 32880.928 | K10: =IFERROR(__xludf.DUMMYFUNCTION("IFERROR(GOOGLEFINANCE(A10, ""price"") - getYahooStockClose(A10), 0)"),-66.06999816894532) -> -66.069998 | L10: =iferror(K10/getYahooStockClose(A10), 0) -> -0.49427694 | M10: =K10*E10 -> -660.69998 | N10: 大盤 | Z10: =IFERROR(__xludf.DUMMYFUNCTION("""COMPUTED_VALUE"""),"債券") -> 債券 | AA10: =IFERROR(__xludf.DUMMYFUNCTION("""COMPUTED_VALUE"""),1157.24) -> 1157.24
A11: GOOGL | B11: =IFERROR(__xludf.DUMMYFUNCTION("INDEX(IMPORTXML(""https://tw.stock.yahoo.com/quote/"" & A11, ""//h1""), 2)"),"Alphabet Inc.") -> Alphabet Inc. | C11: =H11/E11 -> 185.66571 | D11: =getStockPrice(A11) -> 292.81 | E11: =SUMIFS('美股購買'!E:E, '美股購買'!D:D, A11, '美股購買'!B:B, "買進")-SUMIFS('美股購買'!E:E, '美股購買'!D:D, A11, '美股購買'!B:B, "賣出") -> 4.5 | F11: =I11-H11 -> 482.1493 | G11: =F11/H11 -> 0.57708173 | H11: =SUMIFS('美股購買'!$G:$G, '美股購買'!$D:$D, $A11, '美股購買'!B:B, "買進")-SUMIFS('美股購買'!$I:$I, '美股購買'!$D:$D, $A11, '美股購買'!B:B, "賣出") -> 835.4957 | I11: =E11*D11 -> 1317.645 | J11: =SUMIFS('美股購買'!$H:$H, '美股購買'!$D:$D, $A11, '美股購買'!B:B, "買進")-SUMIFS('美股購買'!$J:J, '美股購買'!$D:$D, $A11, '美股購買'!B:B, "賣出") -> 27443.538 | K11: =IFERROR(__xludf.DUMMYFUNCTION("IFERROR(GOOGLEFINANCE(A11, ""price"") - getYahooStockClose(A11), 0)"),8.530001220703127) -> 8.5300012 | L11: =iferror(K11/getYahooStockClose(A11), 0) -> 0.030005633 | M11: =K11*E11 -> 38.385005 | N11: 科技 | Z11: =IFERROR(__xludf.DUMMYFUNCTION("""COMPUTED_VALUE"""),"虛擬貨幣") -> 虛擬貨幣 | AA11: =IFERROR(__xludf.DUMMYFUNCTION("""COMPUTED_VALUE"""),545.51) -> 545.51
A12: AGGU.SW | B12: =IFERROR(__xludf.DUMMYFUNCTION("INDEX(IMPORTXML(""https://tw.stock.yahoo.com/quote/"" & A12, ""//h1""), 2)"),"iShares Core Global Aggregate Bond UCITS ETF USD Hedged (Acc)") -> iShares Core Global Aggregate Bond UCITS ETF USD Hedged (Acc) | C12: =H12/E12 -> 5.60342 | D12: =getStockPrice(A12) -> 5.7862 | E12: =SUMIFS('美股購買'!E:E, '美股購買'!D:D, A12, '美股購買'!B:B, "買進")-SUMIFS('美股購買'!E:E, '美股購買'!D:D, A12, '美股購買'!B:B, "賣出") -> 200 | F12: =I12-H12 -> 36.556 | G12: =F12/H12 -> 0.032619365 | H12: =SUMIFS('美股購買'!$G:$G, '美股購買'!$D:$D, $A12, '美股購買'!B:B, "買進")-SUMIFS('美股購買'!$I:$I, '美股購買'!$D:$D, $A12, '美股購買'!B:B, "賣出") -> 1120.684 | I12: =E12*D12 -> 1157.24 | J12: =SUMIFS('美股購買'!$H:$H, '美股購買'!$D:$D, $A12, '美股購買'!B:B, "買進")-SUMIFS('美股購買'!$J:J, '美股購買'!$D:$D, $A12, '美股購買'!B:B, "賣出") -> 36698 | K12: =IFERROR(__xludf.DUMMYFUNCTION("IFERROR(GOOGLEFINANCE(A12, ""price"") - getYahooStockClose(A12), 0)"),0.0) -> 0 | L12: =iferror(K12/getYahooStockClose(A12), 0) -> 0 | M12: =K12*E12 -> 0 | N12: 債券
A13: ORCL | B13: =IFERROR(__xludf.DUMMYFUNCTION("INDEX(IMPORTXML(""https://tw.stock.yahoo.com/quote/"" & A13, ""//h1""), 2)"),"Oracle Corporation") -> Oracle Corporation | C13: =H13/E13 -> 286.49 | D13: =getStockPrice(A13) -> 225.53 | E13: =SUMIFS('美股購買'!E:E, '美股購買'!D:D, A13, '美股購買'!B:B, "買進")-SUMIFS('美股購買'!E:E, '美股購買'!D:D, A13, '美股購買'!B:B, "賣出") -> 4 | F13: =I13-H13 -> -243.84 | G13: =F13/H13 -> -0.2127823 | H13: =SUMIFS('美股購買'!$G:$G, '美股購買'!$D:$D, $A13, '美股購買'!B:B, "買進")-SUMIFS('美股購買'!$I:$I, '美股購買'!$D:$D, $A13, '美股購買'!B:B, "賣出") -> 1145.96 | I13: =E13*D13 -> 902.12 | J13: =SUMIFS('美股購買'!$H:$H, '美股購買'!$D:$D, $A13, '美股購買'!B:B, "買進")-SUMIFS('美股購買'!$J:J, '美股購買'!$D:$D, $A13, '美股購買'!B:B, "賣出") -> 37618.933 | K13: =IFERROR(__xludf.DUMMYFUNCTION("IFERROR(GOOGLEFINANCE(A13, ""price"") - getYahooStockClose(A13), 0)"),5.039994506835939) -> 5.0399945 | L13: =iferror(K13/getYahooStockClose(A13), 0) -> 0.022858154 | M13: =K13*E13 -> 20.159978 | N13: 科技
A14: AAPL | B14: =IFERROR(__xludf.DUMMYFUNCTION("INDEX(IMPORTXML(""https://tw.stock.yahoo.com/quote/"" & A14, ""//h1""), 2)"),"Apple Inc.") -> Apple Inc. | C14: =H14/E14 -> 254.8355 | D14: =getStockPrice(A14) -> 268.56 | E14: =SUMIFS('美股購買'!E:E, '美股購買'!D:D, A14, '美股購買'!B:B, "買進")-SUMIFS('美股購買'!E:E, '美股購買'!D:D, A14, '美股購買'!B:B, "賣出") -> 4 | F14: =I14-H14 -> 54.898 | G14: =F14/H14 -> 0.053856311 | H14: =SUMIFS('美股購買'!$G:$G, '美股購買'!$D:$D, $A14, '美股購買'!B:B, "買進")-SUMIFS('美股購買'!$I:$I, '美股購買'!$D:$D, $A14, '美股購買'!B:B, "賣出") -> 1019.342 | I14: =E14*D14 -> 1074.24 | J14: =SUMIFS('美股購買'!$H:$H, '美股購買'!$D:$D, $A14, '美股購買'!B:B, "買進")-SUMIFS('美股購買'!$J:J, '美股購買'!$D:$D, $A14, '美股購買'!B:B, "賣出") -> 31090 | K14: =IFERROR(__xludf.DUMMYFUNCTION("IFERROR(GOOGLEFINANCE(A14, ""price"") - getYahooStockClose(A14), 0)"),1.1199975585937523) -> 1.1199976 | L14: =iferror(K14/getYahooStockClose(A14), 0) -> 0.0041878461 | M14: =K14*E14 -> 4.4799902 | N14: 科技
A15: AMZN | B15: =IFERROR(__xludf.DUMMYFUNCTION("INDEX(IMPORTXML(""https://tw.stock.yahoo.com/quote/"" & A15, ""//h1""), 2)"),"Amazon.com, Inc.") -> Amazon.com, Inc. | C15: =H15/E15 -> 205.05429 | D15: =getStockPrice(A15) -> 222.69 | E15: =SUMIFS('美股購買'!E:E, '美股購買'!D:D, A15, '美股購買'!B:B, "買進")-SUMIFS('美股購買'!E:E, '美股購買'!D:D, A15, '美股購買'!B:B, "賣出") -> 3.5 | F15: =I15-H15 -> 61.725 | G15: =F15/H15 -> 0.0860051 | H15: =SUMIFS('美股購買'!$G:$G, '美股購買'!$D:$D, $A15, '美股購買'!B:B, "買進")-SUMIFS('美股購買'!$I:$I, '美股購買'!$D:$D, $A15, '美股購買'!B:B, "賣出") -> 717.69 | I15: =E15*D15 -> 779.415 | J15: =SUMIFS('美股購買'!$H:$H, '美股購買'!$D:$D, $A15, '美股購買'!B:B, "買進")-SUMIFS('美股購買'!$J:J, '美股購買'!$D:$D, $A15, '美股購買'!B:B, "賣出") -> 23559.925 | K15: =IFERROR(__xludf.DUMMYFUNCTION("IFERROR(GOOGLEFINANCE(A15, ""price"") - getYahooStockClose(A15), 0)"),0.13999694824218523) -> 0.13999695 | L15: =iferror(K15/getYahooStockClose(A15), 0) -> 0.0006290584 | M15: =K15*E15 -> 0.48998932 | N15: 科技
A16: meta | B16: =IFERROR(__xludf.DUMMYFUNCTION("INDEX(IMPORTXML(""https://tw.stock.yahoo.com/quote/"" & A16, ""//h1""), 2)"),"Meta Platforms, Inc.") -> Meta Platforms, Inc. | C16: =H16/E16 -> 712.75 | D16: =getStockPrice(A16) -> 590.32 | E16: =SUMIFS('美股購買'!E:E, '美股購買'!D:D, A16, '美股購買'!B:B, "買進")-SUMIFS('美股購買'!E:E, '美股購買'!D:D, A16, '美股購買'!B:B, "賣出") -> 1 | F16: =I16-H16 -> -122.43 | G16: =F16/H16 -> -0.17177131 | H16: =SUMIFS('美股購買'!$G:$G, '美股購買'!$D:$D, $A16, '美股購買'!B:B, "買進")-SUMIFS('美股購買'!$I:$I, '美股購買'!$D:$D, $A16, '美股購買'!B:B, "賣出") -> 712.75 | I16: =E16*D16 -> 590.32 | J16: =SUMIFS('美股購買'!$H:$H, '美股購買'!$D:$D, $A16, '美股購買'!B:B, "買進")-SUMIFS('美股購買'!$J:J, '美股購買'!$D:$D, $A16, '美股購買'!B:B, "賣出") -> 23397.758 | K16: =IFERROR(__xludf.DUMMYFUNCTION("IFERROR(GOOGLEFINANCE(A16, ""price"") - getYahooStockClose(A16), 0)"),-7.3700024414062) -> -7.3700024 | L16: =iferror(K16/getYahooStockClose(A16), 0) -> -0.012330811 | M16: =K16*E16 -> -7.3700024 | N16: 科技
A17: FBTC | B17: =IFERROR(__xludf.DUMMYFUNCTION("INDEX(IMPORTXML(""https://tw.stock.yahoo.com/quote/"" & A17, ""//h1""), 2)"),"Fidelity Wise Origin Bitcoin Fund") -> Fidelity Wise Origin Bitcoin Fund | C17: =H17/E17 -> 80.467143 | D17: =getStockPrice(A17) -> 77.93 | E17: =SUMIFS('美股購買'!E:E, '美股購買'!D:D, A17, '美股購買'!B:B, "買進")-SUMIFS('美股購買'!E:E, '美股購買'!D:D, A17, '美股購買'!B:B, "賣出") -> 7 | F17: =I17-H17 -> -17.76 | G17: =F17/H17 -> -0.031530172 | H17: =SUMIFS('美股購買'!$G:$G, '美股購買'!$D:$D, $A17, '美股購買'!B:B, "買進")-SUMIFS('美股購買'!$I:$I, '美股購買'!$D:$D, $A17, '美股購買'!B:B, "賣出") -> 563.27 | I17: =E17*D17 -> 545.51 | J17: =SUMIFS('美股購買'!$H:$H, '美股購買'!$D:$D, $A17, '美股購買'!B:B, "買進")-SUMIFS('美股購買'!$J:J, '美股購買'!$D:$D, $A17, '美股購買'!B:B, "賣出") -> 18490.712 | K17: =IFERROR(getStockPrice(A17) - getYahooStockClose(A17), 0) -> -2.9700015 | L17: =iferror(K17/getYahooStockClose(A17), 0) -> -0.036712008 | M17: =K17*E17 -> -20.790011 | N17: 虛擬貨幣
A18: MCD | B18: =IFERROR(__xludf.DUMMYFUNCTION("INDEX(IMPORTXML(""https://tw.stock.yahoo.com/quote/"" & A18, ""//h1""), 2)"),"McDonald's Corporation") -> McDonald's Corporation | C18: =H18/E18 -> 289.55208 | D18: =getStockPrice(A18) -> 302.74 | E18: =SUMIFS('美股購買'!E:E, '美股購買'!D:D, A18, '美股購買'!B:B, "買進")-SUMIFS('美股購買'!E:E, '美股購買'!D:D, A18, '美股購買'!B:B, "賣出") -> 2 | F18: =I18-H18 -> 26.37585 | G18: =F18/H18 -> 0.045545952 | H18: =SUMIFS('美股購買'!$G:$G, '美股購買'!$D:$D, $A18, '美股購買'!B:B, "買進")-SUMIFS('美股購買'!$I:$I, '美股購買'!$D:$D, $A18, '美股購買'!B:B, "賣出") -> 579.10415 | I18: =E18*D18 -> 605.48 | J18: =SUMIFS('美股購買'!$H:$H, '美股購買'!$D:$D, $A18, '美股購買'!B:B, "買進")-SUMIFS('美股購買'!$J:J, '美股購買'!$D:$D, $A18, '美股購買'!B:B, "賣出") -> 19053 | K18: =IFERROR(__xludf.DUMMYFUNCTION("IFERROR(GOOGLEFINANCE(A18, ""price"") - getYahooStockClose(A18), 0)"),-1.849996337890616) -> -1.8499963 | L18: =iferror(K18/getYahooStockClose(A18), 0) -> -0.0060737265 | M18: =K18*E18 -> -3.6999927 | N18: 必須消費
A19: LFWD | B19: =IFERROR(__xludf.DUMMYFUNCTION("INDEX(IMPORTXML(""https://tw.stock.yahoo.com/quote/"" & A19, ""//h1""), 2)"),"Lifeward Ltd.") -> Lifeward Ltd. | C19: =H19/E19 -> 1.7618231 | D19: =getStockPrice(A19) -> 0.549 | E19: =SUMIFS('美股購買'!E:E, '美股購買'!D:D, A19, '美股購買'!B:B, "買進")-SUMIFS('美股購買'!E:E, '美股購買'!D:D, A19, '美股購買'!B:B, "賣出") -> 650 | F19: =I19-H19 -> -788.335 | G19: =F19/H19 -> -0.68839096 | H19: =SUMIFS('美股購買'!$G:$G, '美股購買'!$D:$D, $A19, '美股購買'!B:B, "買進")-SUMIFS('美股購買'!$I:$I, '美股購買'!$D:$D, $A19, '美股購買'!B:B, "賣出") -> 1145.185 | I19: =E19*D19 -> 356.85 | J19: =SUMIFS('美股購買'!$H:$H, '美股購買'!$D:$D, $A19, '美股購買'!B:B, "買進")-SUMIFS('美股購買'!$J:J, '美股購買'!$D:$D, $A19, '美股購買'!B:B, "賣出") -> 36710.675 | K19: =IFERROR(__xludf.DUMMYFUNCTION("IFERROR(GOOGLEFINANCE(A19, ""price"") - getYahooStockClose(A19), 0)"),-0.05600000619888301) -> -0.056000006 | L19: =iferror(K19/getYahooStockClose(A19), 0) -> -0.09240925 | M19: =K19*E19 -> -36.400004 | N19: 科技
A20: ABNB | B20: =IFERROR(__xludf.DUMMYFUNCTION("INDEX(IMPORTXML(""https://tw.stock.yahoo.com/quote/"" & A20, ""//h1""), 2)"),"Airbnb, Inc.") -> Airbnb, Inc. | C20: =H20/E20 -> 129.94405 | D20: =getStockPrice(A20) -> 114.44 | E20: =SUMIFS('美股購買'!E:E, '美股購買'!D:D, A20, '美股購買'!B:B, "買進")-SUMIFS('美股購買'!E:E, '美股購買'!D:D, A20, '美股購買'!B:B, "賣出") -> 3 | F20: =I20-H20 -> -46.51215 | G20: =F20/H20 -> -0.11931327 | H20: =SUMIFS('美股購買'!$G:$G, '美股購買'!$D:$D, $A20, '美股購買'!B:B, "買進")-SUMIFS('美股購買'!$I:$I, '美股購買'!$D:$D, $A20, '美股購買'!B:B, "賣出") -> 389.83215 | I20: =E20*D20 -> 343.32 | J20: =SUMIFS('美股購買'!$H:$H, '美股購買'!$D:$D, $A20, '美股購買'!B:B, "買進")-SUMIFS('美股購買'!$J:J, '美股購買'!$D:$D, $A20, '美股購買'!B:B, "賣出") -> 12814 | K20: =IFERROR(__xludf.DUMMYFUNCTION("IFERROR(GOOGLEFINANCE(A20, ""price"") - getYahooStockClose(A20), 0)"),-0.9799981689453148) -> -0.97999817 | L20: =iferror(K20/getYahooStockClose(A20), 0) -> -0.0084907138 | M20: =K20*E20 -> -2.9399945 | N20: 必須消費
A21: TSLZ | B21: =IFERROR(__xludf.DUMMYFUNCTION("INDEX(IMPORTXML(""https://tw.stock.yahoo.com/quote/"" & A21, ""//h1""), 2)"),"T-Rex 2X Inverse Tesla Daily Target ETF") -> T-Rex 2X Inverse Tesla Daily Target ETF | C21: =H21/E21 -> 101.1 | D21: =getStockPrice(A21) -> 15.57 | E21: =SUMIFS('美股購買'!E:E, '美股購買'!D:D, A21, '美股購買'!B:B, "買進")-SUMIFS('美股購買'!E:E, '美股購買'!D:D, A21, '美股購買'!B:B, "賣出") -> 5 | F21: =I21-H21 -> -427.65 | G21: =F21/H21 -> -0.84599407 | H21: =SUMIFS('美股購買'!$G:$G, '美股購買'!$D:$D, $A21, '美股購買'!B:B, "買進")-SUMIFS('美股購買'!$I:$I, '美股購買'!$D:$D, $A21, '美股購買'!B:B, "賣出") -> 505.5 | I21: =E21*D21 -> 77.85 | J21: =SUMIFS('美股購買'!$H:$H, '美股購買'!$D:$D, $A21, '美股購買'!B:B, "買進")-SUMIFS('美股購買'!$J:J, '美股購買'!$D:$D, $A21, '美股購買'!B:B, "賣出") -> 16594.271 | K21: =IFERROR(__xludf.DUMMYFUNCTION("IFERROR(GOOGLEFINANCE(A21, ""price"") - getYahooStockClose(A21), 0)"),-0.21999996185302706) -> -0.21999996 | L21: =iferror(K21/getYahooStockClose(A21), 0) -> -0.013932867 | M21: =K21*E21 -> -1.0999998 | N21: 科技

Sheet 台股庫存
A1: 股票代號 | B1: 股票名稱 | C1: 成本 | D1: 現價 | E1: 持有股數 | F1: 損益 | G1: 損益率 | H1: 總投資成本 | I1: 市值 | J1: 總市值 | K1: =SUM(I:I) -> 299509.45 | L1: 總成本 | M1: =SUM(H:H) -> 240415.82 | N1: 總損益 | O1: =K1-M1 -> 59093.63 | P1: 總損益率 | Q1: =O1/M1 -> 0.24579759
A2: 1432 | B2: =IFERROR(__xludf.DUMMYFUNCTION("INDEX(IMPORTXML(""https://tw.stock.yahoo.com/quote/"" & A2, ""//h1""), 2) "),"大魯閣") -> 大魯閣 | C2: =H2/E2 -> 20 | D2: =getStockPrice(A2 & ".TW") -> 17.15 | E2: =SUMIFS('台股購買'!$D:$D, '台股購買'!$C:$C, $A2, '台股購買'!B:B, "買進")-sumifs('台股購買'!D:D, '台股購買'!C:C, $A2, '台股購買'!B:B, "賣出") -> 1 | F2: =I2-H2 -> -2.85 | G2: =F2/H2 -> -0.1425 | H2: =SUMIFS('台股購買'!$F:$F, '台股購買'!$C:$C, $A2, '台股購買'!B:B, "買進")+SUMIFS('台股購買'!$G:$G, '台股購買'!$C:$C, $A2, '台股購買'!B:B, "買進")-SUMIFS('台股購買'!$H:H, '台股購買'!$C:$C, $A2, '台股購買'!B:B, "賣出") -> 20 | I2: =E2*D2 -> 17.15
A3: 006208 | B3: =IFERROR(__xludf.DUMMYFUNCTION("INDEX(IMPORTXML(""https://tw.stock.yahoo.com/quote/"" & A3, ""//h1""), 2) "),"富邦台50") -> 富邦台50 | C3: =H3/E3 -> 116.44382 | D3: =getStockPrice(A3 & ".TW") -> 141.55 | E3: =SUMIFS('台股購買'!$D:$D, '台股購買'!$C:$C, $A3, '台股購買'!B:B, "買進")-sumifs('台股購買'!D:D, '台股購買'!C:C, $A3, '台股購買'!B:B, "賣出") -> 34 | F3: =I3-H3 -> 853.61 | G3: =F3/H3 -> 0.21560763 | H3: =SUMIFS('台股購買'!$F:$F, '台股購買'!$C:$C, $A3, '台股購買'!B:B, "買進")+SUMIFS('台股購買'!$G:$G, '台股購買'!$C:$C, $A3, '台股購買'!B:B, "買進")-SUMIFS('台股購買'!$H:H, '台股購買'!$C:$C, $A3, '台股購買'!B:B, "賣出") -> 3959.09 | I3: =E3*D3 -> 4812.7
A4: 009800 | B4: =IFERROR(__xludf.DUMMYFUNCTION("INDEX(IMPORTXML(""https://tw.stock.yahoo.com/quote/"" & A4, ""//h1""), 2) "),"中信NASDAQ") -> 中信NASDAQ | C4: =H4/E4 -> 10.008462 | D4: =getStockPrice(A4 & ".TW") -> 10.92 | E4: =SUMIFS('台股購買'!$D:$D, '台股購買'!$C:$C, $A4, '台股購買'!B:B, "買進")-sumifs('台股購買'!D:D, '台股購買'!C:C, $A4, '台股購買'!B:B, "賣出") -> 1300 | F4: =I4-H4 -> 1185 | G4: =F4/H4 -> 0.091076781 | H4: =SUMIFS('台股購買'!$F:$F, '台股購買'!$C:$C, $A4, '台股購買'!B:B, "買進")+SUMIFS('台股購買'!$G:$G, '台股購買'!$C:$C, $A4, '台股購買'!B:B, "買進")-SUMIFS('台股購買'!$H:H, '台股購買'!$C:$C, $A4, '台股購買'!B:B, "賣出") -> 13011 | I4: =E4*D4 -> 14196
A5: 2330 | B5: =IFERROR(__xludf.DUMMYFUNCTION("INDEX(IMPORTXML(""https://tw.stock.yahoo.com/quote/"" & A5, ""//h1""), 2) "),"台積電") -> 台積電 | C5: =H5/E5 -> 1462.0714 | D5: =getStockPrice(A5 & ".TW") -> 1455 | E5: =SUMIFS('台股購買'!$D:$D, '台股購買'!$C:$C, $A5, '台股購買'!B:B, "買進")-sumifs('台股購買'!D:D, '台股購買'!C:C, $A5, '台股購買'!B:B, "賣出") -> 42 | F5: =I5-H5 -> -297 | G5: =F5/H5 -> -0.0048365821 | H5: =SUMIFS('台股購買'!$F:$F, '台股購買'!$C:$C, $A5, '台股購買'!B:B, "買進")+SUMIFS('台股購買'!$G:$G, '台股購買'!$C:$C, $A5, '台股購買'!B:B, "買進")-SUMIFS('台股購買'!$H:H, '台股購買'!$C:$C, $A5, '台股購買'!B:B, "賣出") -> 61407 | I5: =E5*D5 -> 61110
A6: 0050 | B6: =IFERROR(__xludf.DUMMYFUNCTION("INDEX(IMPORTXML(""https://tw.stock.yahoo.com/quote/"" & A6, ""//h1""), 2) "),"元大台灣50") -> 元大台灣50 | C6: =H6/E6 -> 45.716346 | D6: =getStockPrice(A6 & ".TW") -> 61.9 | E6: =SUMIFS('台股購買'!$D:$D, '台股購買'!$C:$C, $A6, '台股購買'!B:B, "買進")-sumifs('台股購買'!D:D, '台股購買'!C:C, $A6, '台股購買'!B:B, "賣出") -> 3544 | F6: =I6-H6 -> 57354.87 | G6: =F6/H6 -> 0.35400148 | H6: =SUMIFS('台股購買'!$F:$F, '台股購買'!$C:$C, $A6, '台股購買'!B:B, "買進")+SUMIFS('台股購買'!$G:$G, '台股購買'!$C:$C, $A6, '台股購買'!B:B, "買進")-SUMIFS('台股購買'!$H:H, '台股購買'!$C:$C, $A6, '台股購買'!B:B, "賣出") -> 162018.73 | I6: =E6*D6 -> 219373.6

Sheet 美股購買
A1: 時間 | B1: 買賣別 | C1: 卷商 | D1: 股票代號 | E1: 數量 | F1: 成交價格 | G1: 市值 | H1: 台幣交割 | I1: 成本(USD) | J1: 成本(TWD) | K1: 第 1 欄 | L1: 總成本 | M1: 時間 | N1: 美金 | O1: 台幣 | P1: 補貼 | Q1: 匯率 | T1: 時間 | U1: 股票代號 | V1: 持股數 | W1: 每股股息 | X1: 股息金額 | Y1: 手續費 | Z1: 淨股利
A2: 45681.098 | B2: 買進 | C2: 富邦 | D2: TSLA | E2: 1 | F2: 409.73 | G2: =IF(C2="富邦", IF(B2="買進", E2*F2*1.0025, IF(B2="賣出", E2*F2*0.9975, E2*F2)), E2*F2) -> 410.75432 | H2: 13585 | L2: =sum(G:G) -> 66727.294 | M2: 45700 | N2: =15218.84-25 -> 15193.84 | O2: 500149 | P2: 25 | Q2: =(O2-150)/N2 -> 32.908007 | T2: 45734 | U2: 00878 | V2: 1000 | W2: 0.5 | X2: =V2*W2 -> 500 | Y2: 10 | Z2: =X2-Y2 -> 490
A3: 45681.099 | B3: 買進 | C3: 富邦 | D3: NVDA | E3: 1 | F3: 143.56 | G3: =IF(C3="富邦", IF(B3="買進", E3*F3*1.0025, IF(B3="賣出", E3*F3*0.9975, E3*F3)), E3*F3) -> 143.9189 | H3: 3979 | M3: 45709 | N3: =10059.53-25 -> 10034.53 | O3: 329851 | P3: 25 | Q3: =(O3-150)/N3 -> 32.856646
A4: 45684.062 | B4: 買進 | C4: 富邦 | D4: NVDA | E4: 3 | F4: 119.68 | G4: =IF(C4="富邦", IF(B4="買進", E4*F4*1.0025, IF(B4="賣出", E4*F4*0.9975, E4*F4)), E4*F4) -> 359.9376 | H4: 11905 | M4: 45727 | N4: 4248.18 | O4: 140000 | P4: 0 | Q4: =(O4-150)/N4 -> 32.91998
A5: 45685.964 | B5: 買進 | C5: 富邦 | D5: NVDA | E5: 5 | F5: 119.64 | G5: =IF(C5="富邦", IF(B5="買進", E5*F5*1.0025, IF(B5="賣出", E5*F5*0.9975, E5*F5)), E5*F5) -> 599.6955 | H5: 19834 | M5: 45792 | N5: -32.83 | O5: 1000 | Q5: =(O5)/N5 -> -30.459945
A6: 45687.979 | B6: 買進 | C6: 富邦 | D6: NVDA | E6: 1 | F6: 120 | G6: =IF(C6="富邦", IF(B6="買進", E6*F6*1.0025, IF(B6="賣出", E6*F6*0.9975, E6*F6)), E6*F6) -> 120.3 | H6: 4760
A7: 45691.954 | B7: 買進 | C7: 富邦 | D7: TSLA | E7: 1 | F7: 380 | G7: =IF(C7="富邦", IF(B7="買進", E7*F7*1.0025, IF(B7="賣出", E7*F7*0.9975, E7*F7)), E7*F7) -> 380.95 | H7: 12565
A8: 45692.005 | B8: 買進 | C8: 富邦 | D8: MCD | E8: 2 | F8: 288.83 | G8: =IF(C8="富邦", IF(B8="買進", E8*F8*1.0025, IF(B8="賣出", E8*F8*0.9975, E8*F8)), E8*F8) -> 579.10415 | H8: 19053
A9: 45693.112 | B9: 買進 | C9: 富邦 | D9: GOOGL | E9: 2 | F9: 191.14 | G9: =IF(C9="富邦", IF(B9="買進", E9*F9*1.0025, IF(B9="賣出", E9*F9*0.9975, E9*F9)), E9*F9) -> 383.2357 | H9: 12597
A10: 45693.112 | B10: 買進 | C10: 富邦 | D10: ABNB | E10: 3 | F10: 129.62 | G10: =IF(C10="富邦", IF(B10="買進", E10*F10*1.0025, IF(B10="賣出", E10*F10*0.9975, E10*F10)), E10*F10) -> 389.83215 | H10: 12814 | L10: =H2+H7+H11 -> 50668 | M10: 台幣 | N10: =500149+329851+140000+24-1000 -> 969024 | P10: =P11*'總計'!J6 -> 1260876.2
